<?xml version="1.0" ?>
<!-- =================================================================================== -->
<!-- |    This document was autogenerated by xacro from stretch_description_dex.xacro  | -->
<!-- |    EDITING THIS FILE BY HAND IS NOT RECOMMENDED                                 | -->
<!-- =================================================================================== -->
<robot name="stretch_description">
  <link name="link_wrist_yaw_bottom">
    <inertial>
      <origin rpy="0 0 0" xyz="-0.012839101377342 -0.0382787718640742 -0.0228400332263617"/>
      <mass value="0.0988906816399982"/>
      <inertia ixx="2.60067866573596E-05" ixy="-6.73176267521354E-06" ixz="-2.43476436723672E-06" iyy="5.99482946819923E-06" iyz="-3.39642410492401E-06" izz="2.56907114334732E-05"/>
    </inertial>
    <visual>
      <origin rpy="0 0 0" xyz="0 0 0"/>
      <geometry>
        <mesh filename="meshes/link_wrist_yaw_bottom.STL"/>
      </geometry>
      <material name="">
        <color rgba="0.792156862745098 0.819607843137255 0.933333333333333 1"/>
      </material>
    </visual>
    <collision>
      <origin rpy="0 0 0" xyz="0 0 0"/>
      <geometry>
        <mesh filename="meshes/link_wrist_yaw_bottom.STL"/>
      </geometry>
    </collision>
  </link>
  <joint name="joint_wrist_yaw_bottom" type="fixed">
    <origin rpy="-3.14159265358979 1.13367999021379E-14 1.57079632679489" xyz="0 0 0"/>
    <parent link="link_wrist_yaw"/>
    <child link="link_wrist_yaw_bottom"/>
    <axis xyz="0 0 0"/>
  </joint>
  <link name="link_wrist_pitch">
    <inertial>
      <origin rpy="0 0 0" xyz="-0.00310609611067142 -0.0150777141465843 0.0204734587925901"/>
      <mass value="0.0701267146295583"/>
      <inertia ixx="2.55965614980905E-06" ixy="-1.47551515167608E-06" ixz="-6.31436085977252E-08" iyy="3.43968637386282E-06" iyz="-4.17813567208843E-07" izz="4.53568668211393E-06"/>
    </inertial>
    <visual>
      <origin rpy="0 0 0" xyz="0 0 0"/>
      <geometry>
        <mesh filename="meshes/link_wrist_pitch.STL"/>
      </geometry>
      <material name="">
        <color rgba="0.792156862745098 0.819607843137255 0.933333333333333 1"/>
      </material>
    </visual>
    <collision>
      <origin rpy="0 0 0" xyz="0 0 0"/>
      <geometry>
        <mesh filename="meshes/link_wrist_pitch.STL"/>
      </geometry>
    </collision>
  </link>
  <joint name="joint_wrist_pitch" type="revolute">
    <origin rpy="1.5707963267949 -8.12895570882604E-15 -3.14159265358979" xyz="0 -0.0195500000000002 -0.0247499999999984"/>
    <parent link="link_wrist_yaw_bottom"/>
    <child link="link_wrist_pitch"/>
    <axis xyz="0 0 -1"/>
    <limit effort="100" lower="-1.57" upper="0.56" velocity="1.0"/>
  </joint>
  <link name="link_wrist_roll">
    <inertial>
      <origin rpy="0 0 0" xyz="9.63118473862323E-15 -6.38378239159465E-15 0.00768048802649798"/>
      <mass value="0.00585666394358811"/>
      <inertia ixx="2.55965614980905E-06" ixy="-1.47551515167608E-06" ixz="-6.31436085977252E-08" iyy="3.43968637386282E-06" iyz="-4.17813567208843E-07" izz="4.53568668211393E-06"/>
    </inertial>
    <visual>
      <origin rpy="0 0 0" xyz="0 0 0"/>
      <geometry>
        <mesh filename="meshes/link_wrist_roll.STL"/>
      </geometry>
      <material name="">
        <color rgba="0.792156862745098 0.819607843137255 0.933333333333333 1"/>
      </material>
    </visual>
    <collision>
      <origin rpy="0 0 0" xyz="0 0 0"/>
      <geometry>
        <mesh filename="meshes/link_wrist_roll.STL"/>
      </geometry>
    </collision>
  </link>
  <joint name="joint_wrist_roll" type="revolute">
    <origin rpy="3.14159265358979 1.5707963267949 0" xyz="-0.0188587444076125 -0.0239999999998942 0.01955"/>
    <parent link="link_wrist_pitch"/>
    <child link="link_wrist_roll"/>
    <axis xyz="0 0 1"/>
    <limit effort="100" lower="-3.14" upper="3.14" velocity="1.0"/>
  </joint>
  <link name="link_straight_gripper">
    <inertial>
      <origin rpy="0 0 0" xyz="0.00150764845432383 -0.00711581846201287 0.0399737901417758"/>
      <mass value="0.0496384234458284"/>
      <inertia ixx="5.61461154156397E-06" ixy="8.29518962984231E-07" ixz="-2.41382921888194E-06" iyy="1.11504692003467E-05" iyz="9.76174898123369E-07" izz="6.63803357903882E-06"/>
    </inertial>
    <visual>
      <origin rpy="0 0 0" xyz="0 0 0"/>
      <geometry>
        <mesh filename="meshes/link_straight_gripper.STL"/>
      </geometry>
      <material name="">
        <color rgba="0.792156862745098 0.819607843137255 0.933333333333333 1"/>
      </material>
    </visual>
    <collision>
      <origin rpy="0 0 0" xyz="0 0 0"/>
      <geometry>
        <mesh filename="meshes/link_straight_gripper.STL"/>
      </geometry>
    </collision>
  </link>
  <joint name="joint_straight_gripper" type="fixed">
    <origin rpy="3.54987407349455E-30 3.24021254484265E-20 -3.14159265358979" xyz="0 0 0.0155"/>
    <parent link="link_wrist_roll"/>
    <child link="link_straight_gripper"/>
    <axis xyz="0 0 0"/>
  </joint>
  <link name="link_gripper_finger_right">
    <inertial>
      <origin rpy="0 0 0" xyz="-0.094981 -0.0080152 -2.2204E-16"/>
      <mass value="0.047621"/>
      <inertia ixx="0.001" ixy="0" ixz="0" iyy="0.001" iyz="0" izz="0.001"/>
    </inertial>
    <visual>
      <origin rpy="0 0 0" xyz="0 0 0"/>
      <geometry>
        <mesh filename="meshes/link_gripper_finger_right.STL"/>
      </geometry>
      <material name="">
        <color rgba="0.79216 0.81961 0.93333 1"/>
      </material>
    </visual>
    <collision>
      <origin rpy="0 0 0" xyz="0 0 0"/>
      <geometry>
        <mesh filename="meshes/link_gripper_finger_right.STL"/>
      </geometry>
    </collision>
  </link>
  <joint name="joint_gripper_finger_right" type="revolute">
    <origin rpy="1.5708 1.5708 0" xyz="-0.018599 0.003 0.033689"/>
    <parent link="link_straight_gripper"/>
    <child link="link_gripper_finger_right"/>
    <axis xyz="0 0 1"/>
    <limit effort="100" lower="-0.6" upper="0.6" velocity="1.0"/>
  </joint>
  <link name="link_gripper_fingertip_right">
    <inertial>
      <origin rpy="0 0 0" xyz="2.83785970833783E-08 6.75131661687089E-09 0.00812578923434215"/>
      <mass value="0.00382160881468841"/>
      <inertia ixx="0.001" ixy="0" ixz="0" iyy="0.001" iyz="0" izz="0.001"/>
    </inertial>
    <visual>
      <origin rpy="0 0 0" xyz="0 0 0"/>
      <geometry>
        <mesh filename="meshes/link_gripper_fingertip_right.STL"/>
      </geometry>
      <material name="">
        <color rgba="0.250980392156863 0.250980392156863 0.250980392156863 1"/>
      </material>
    </visual>
    <collision>
      <origin rpy="0 0 0" xyz="0 0 0"/>
      <geometry>
        <mesh filename="meshes/link_gripper_fingertip_right.STL"/>
      </geometry>
    </collision>
  </link>
  <joint name="joint_gripper_fingertip_right" type="fixed">
    <origin rpy="-1.57079632679483 -3.43320051448326E-14 0.540456056432235" xyz="-0.190596948563868 -0.015 0"/>
    <parent link="link_gripper_finger_right"/>
    <child link="link_gripper_fingertip_right"/>
    <axis xyz="0 0 0"/>
  </joint>
  <link name="link_gripper_finger_left">
    <inertial>
      <origin rpy="0 0 0" xyz="0.0949811095686165 -0.00801522758203194 1.38777878078145E-15"/>
      <mass value="0.0476207785199479"/>
      <inertia ixx="0.001" ixy="0" ixz="0" iyy="0.001" iyz="0" izz="0.001"/>
    </inertial>
    <visual>
      <origin rpy="3.141592653589793 0 0" xyz="0 0 0"/>
      <geometry>
        <mesh filename="meshes/link_gripper_finger_left.STL"/>
      </geometry>
      <material name="">
        <color rgba="0.792156862745098 0.819607843137255 0.933333333333333 1"/>
      </material>
    </visual>
    <collision>
      <origin rpy="1.5707963267948966 0 0" xyz="0 0 0"/>
      <geometry>
        <mesh filename="meshes/link_gripper_finger_left.STL"/>
      </geometry>
    </collision>
  </link>
  <joint name="joint_gripper_finger_left" type="revolute">
    <origin rpy="1.5708 -1.5708 0" xyz="0.018599 0.003 0.033689"/>
    <parent link="link_straight_gripper"/>
    <child link="link_gripper_finger_left"/>
    <axis xyz="0 0 -1"/>
    <limit effort="100" lower="-0.6" upper="0.6" velocity="1.0"/>
  </joint>
  <link name="link_gripper_fingertip_left">
    <inertial>
      <origin rpy="0 0 0" xyz="-2.59496317767116E-08 -6.65612598371723E-09 0.00812579036862837"/>
      <mass value="0.00382160686584851"/>
      <inertia ixx="0.001" ixy="0" ixz="0" iyy="0.001" iyz="0" izz="0.001"/>
    </inertial>
    <visual>
      <origin rpy="0 0 0" xyz="0 0 0"/>
      <geometry>
        <mesh filename="meshes/link_gripper_fingertip_left.STL"/>
      </geometry>
      <material name="">
        <color rgba="0.250980392156863 0.250980392156863 0.250980392156863 1"/>
      </material>
    </visual>
    <collision>
      <origin rpy="0 0 0" xyz="0 0 0"/>
      <geometry>
        <mesh filename="meshes/link_gripper_fingertip_left.STL"/>
      </geometry>
    </collision>
  </link>
  <joint name="joint_gripper_fingertip_left" type="fixed">
    <origin rpy="1.57079632679496 4.51275387511463E-14 2.60113659715756" xyz="0.190596948563868 -0.015 0"/>
    <parent link="link_gripper_finger_left"/>
    <child link="link_gripper_fingertip_left"/>
    <axis xyz="0 0 0"/>
  </joint>
  <link name="link_grasp_center">
  </link>
  <joint name="joint_grasp_center" type="fixed">
    <origin rpy="-1.5707963267949 -1.5707963267949 0" xyz="0 0 0.23"/>
    <parent link="link_straight_gripper"/>
    <child link="link_grasp_center"/>
  </joint>
  <!--<xacro:include filename="stretch_gripper.xacro" /> -->
  <!--<xacro:include filename="stretch_gripper_with_puller.xacro" />-->
  <!--<xacro:include filename="stretch_dry_erase_marker.xacro" />-->
  <link name="base_link">
    <inertial>
      <origin rpy="0 0 0" xyz="-0.11587 0.0019426 0.093621"/>
      <mass value="1.1912"/>
      <inertia ixx="0.0034667" ixy="-5.0568E-06" ixz="0.00042861" iyy="0.0052744" iyz="-5.766E-05" izz="0.0047945"/>
    </inertial>
    <visual>
      <origin rpy="0 0 0" xyz="0 0 0"/>
      <geometry>
        <mesh filename="meshes/base_link.STL"/>
      </geometry>
      <material name="">
        <color rgba="0.79216 0.81961 0.93333 1"/>
      </material>
    </visual>
    <collision>
      <origin rpy="0 0 0" xyz="0 0 0"/>
      <geometry>
        <mesh filename="meshes/base_link.STL"/>
      </geometry>
    </collision>
  </link>
  <link name="link_right_wheel">
    <inertial>
      <origin rpy="0 0 0" xyz="1.1719E-11 2.0783E-11 0.037544"/>
      <mass value="0.0042721"/>
      <inertia ixx="0.001" ixy="0" ixz="0" iyy="0.001" iyz="0" izz="0.001"/>
    </inertial>
    <visual>
      <origin rpy="0 0 0" xyz="0 0 0"/>
      <geometry>
        <mesh filename="meshes/link_right_wheel.STL"/>
      </geometry>
      <material name="">
        <color rgba="0.79216 0.81961 0.93333 1"/>
      </material>
    </visual>
    <collision>
      <origin rpy="0 0 0" xyz="0 0 0"/>
      <geometry>
        <mesh filename="meshes/link_right_wheel.STL"/>
      </geometry>
    </collision>
  </link>
  <joint name="joint_right_wheel" type="continuous">
    <origin rpy="-1.5708 1.2717E-16 4.8006E-17" xyz="0 -0.17035 0.0508"/>
    <parent link="base_link"/>
    <child link="link_right_wheel"/>
    <axis xyz="0 0 1"/>
    <dynamics damping="21.75" friction="10.48" spring_reference="0" spring_stiffness="0"/>
  </joint>
  <link name="link_left_wheel">
    <inertial>
      <origin rpy="0 0 0" xyz="-2.0783E-11 -1.1719E-11 -0.037544"/>
      <mass value="0.0042721"/>
      <inertia ixx="0.001" ixy="0" ixz="0" iyy="0.001" iyz="0" izz="0.001"/>
    </inertial>
    <visual>
      <origin rpy="0 0 0" xyz="0 0 0"/>
      <geometry>
        <mesh filename="meshes/link_left_wheel.STL"/>
      </geometry>
      <material name="">
        <color rgba="0.79216 0.81961 0.93333 1"/>
      </material>
    </visual>
    <collision>
      <origin rpy="0 0 0" xyz="0 0 0"/>
      <geometry>
        <mesh filename="meshes/link_left_wheel.STL"/>
      </geometry>
    </collision>
  </link>
  <joint name="joint_left_wheel" type="continuous">
    <origin rpy="-1.5708 2.6317E-16 -8.2057E-19" xyz="0 0.17035 0.0508"/>
    <parent link="base_link"/>
    <child link="link_left_wheel"/>
    <axis xyz="0 0 1"/>
    <dynamics damping="21.75" friction="10.48" spring_reference="0" spring_stiffness="0"/>
  </joint>
  <link name="caster_link">
    <collision>
      <geometry>
        <sphere radius="0.032"/>
      </geometry>
      <origin rpy="0 0 0" xyz="0 0 0"/>
      <surface>
        <friction>
          <ode>
            <mu>0</mu>
            <mu2>0</mu2>
            <slip1>1.0</slip1>
            <slip2>1.0</slip2>
          </ode>
        </friction>
      </surface>
    </collision>
    <visual>
      <origin rpy="0 0 0" xyz="0 0 0"/>
      <geometry>
        <mesh filename="meshes/omni_wheel_m.STL"/>
      </geometry>
      <material name="">
        <color rgba="0.792156862745098 0.819607843137255 0.933333333333333 1"/>
      </material>
    </visual>
    <inertial>
      <mass value="0.01"/>
      <origin xyz="0 0 0"/>
      <inertia ixx="0.001" ixy="0" ixz="0" iyy="0.001" iyz="0" izz="0.001"/>
    </inertial>
  </link>
  <joint name="caster_joint" type="fixed">
    <parent link="base_link"/>
    <child link="caster_link"/>
    <origin rpy="-1.5707963267948966 0 0" xyz="-0.245 0.0 0.032"/>
    <axis xyz="0 0 1"/>
  </joint>
  <link name="link_mast">
    <inertial>
      <origin rpy="0 0 0" xyz="2.0817E-17 0.7075 -2.7756E-17"/>
      <mass value="1.8285"/>
      <inertia ixx="0.0709854511954588" ixy="-0.00433428742758457" ixz="-0.000186110788697573" iyy="0.000437922053342648" iyz="-0.00288788257713431" izz="0.071104808501661"/>
    </inertial>
    <visual>
      <origin rpy="0 0 0" xyz="0 0 0"/>
      <geometry>
        <mesh filename="meshes/link_mast.STL"/>
      </geometry>
      <material name="">
        <color rgba="0.79216 0.81961 0.93333 1"/>
      </material>
    </visual>
    <collision>
      <origin rpy="0 0 0" xyz="0 0 0"/>
      <geometry>
        <mesh filename="meshes/link_mast.STL"/>
      </geometry>
    </collision>
  </link>
  <joint name="joint_mast" type="fixed">
    <origin rpy="1.5708 0 4.8006E-17" xyz="-0.067 0.135 0.0284"/>
    <parent link="base_link"/>
    <child link="link_mast"/>
    <axis xyz="0 0 0"/>
  </joint>
  <link name="link_lift">
    <inertial>
      <origin rpy="0 0 0" xyz="-0.031727 0.038403 0.013361"/>
      <mass value="0.27218"/>
      <inertia ixx="0.00052571" ixy="0.00014899" ixz="-1.9258E-05" iyy="0.00030679" iyz="-6.2451E-06" izz="0.00037324"/>
    </inertial>
    <visual>
      <origin rpy="0 0 0" xyz="0 0 0"/>
      <geometry>
        <mesh filename="meshes/link_lift.STL"/>
      </geometry>
      <material name="">
        <color rgba="0.79216 0.81961 0.93333 1"/>
      </material>
    </visual>
    <collision>
      <origin rpy="0 0 0" xyz="0 0 0"/>
      <geometry>
        <mesh filename="meshes/link_lift.STL"/>
      </geometry>
    </collision>
  </link>
  <joint name="joint_lift" type="prismatic">
    <origin rpy="-1.5708 1.5708 0" xyz="-0.037385 0.1666 0"/>
    <parent link="link_mast"/>
    <child link="link_lift"/>
    <axis xyz="0 0 1"/>
    <!-- for now: hand copied range_m: from lift: from ~/repos/stretch_fleet/stretch-re1-1001/stretch_re1_factory_params.yaml -->
    <!--<limit effort="100" lower="0.0" upper="1.095" velocity="1.0"/>-->
    <!-- copied value did not reach the top of mesh model with GUI sliders and RViz -->
    <limit effort="100" lower="0.0" upper="1.1" velocity="1.0"/>
  </joint>
  <link name="link_arm_l4">
    <inertial>
      <origin rpy="0 0 0" xyz="-1.0146E-06 -1.9719E-05 -0.094738"/>
      <mass value="0.068095"/>
      <inertia ixx="0.0001256" ixy="-5.6914E-12" ixz="6.0647E-09" iyy="0.0001256" iyz="1.1787E-07" izz="1.1091E-10"/>
    </inertial>
    <visual>
      <origin rpy="0 0 0" xyz="0 0 0"/>
      <geometry>
        <mesh filename="meshes/link_arm_l4.STL"/>
      </geometry>
      <material name="">
        <color rgba="0.79216 0.81961 0.93333 1"/>
      </material>
    </visual>
    <collision>
      <origin rpy="0 0 0" xyz="0 0 0"/>
      <geometry>
        <mesh filename="meshes/link_arm_l4.STL"/>
      </geometry>
    </collision>
  </link>
  <joint name="joint_arm_l4" type="fixed">
    <origin rpy="1.5708 2.4721E-15 -1.5708" xyz="-0.2547 0 0"/>
    <parent link="link_lift"/>
    <child link="link_arm_l4"/>
    <axis xyz="0 0 0"/>
  </joint>
  <link name="link_arm_l3">
    <inertial>
      <origin rpy="0 0 0" xyz="-5.13853606326845E-07 -1.99844969271112E-05 -0.0971104963726614"/>
      <mass value="0.0628927381893134"/>
      <inertia ixx="0.001" ixy="0" ixz="0" iyy="0.001" iyz="0" izz="0.001"/>
    </inertial>
    <visual>
      <origin rpy="0 0 0" xyz="0 0 0"/>
      <geometry>
        <mesh filename="meshes/link_arm_l3.STL"/>
      </geometry>
      <material name="">
        <color rgba="0.792156862745098 0.819607843137255 0.933333333333333 1"/>
      </material>
    </visual>
    <collision>
      <origin rpy="0 0 0" xyz="0 0 0"/>
      <geometry>
        <mesh filename="meshes/link_arm_l3.STL"/>
      </geometry>
    </collision>
  </link>
  <joint name="joint_arm_l3" type="prismatic">
    <origin rpy="7.68831233799385E-30 2.36716479416092E-30 2.29652732251143E-17" xyz="0 0 0.013"/>
    <parent link="link_arm_l4"/>
    <child link="link_arm_l3"/>
    <axis xyz="0 0 1"/>
    <!-- 0.13 = 0.52/4-->
    <limit effort="100" lower="0.0" upper="0.13" velocity="1.0"/>
  </joint>
  <link name="link_arm_l2">
    <inertial>
      <origin rpy="0 0 0" xyz="-5.17421949435687E-07 -2.02045301450349E-05 -0.0968815475684904"/>
      <mass value="0.0571386353275368"/>
      <inertia ixx="0.001" ixy="0" ixz="0" iyy="0.001" iyz="0" izz="0.001"/>
    </inertial>
    <visual>
      <origin rpy="0 0 0" xyz="0 0 0"/>
      <geometry>
        <mesh filename="meshes/link_arm_l2.STL"/>
      </geometry>
      <material name="">
        <color rgba="0.792156862745098 0.819607843137255 0.933333333333333 1"/>
      </material>
    </visual>
    <collision>
      <origin rpy="0 0 0" xyz="0 0 0"/>
      <geometry>
        <mesh filename="meshes/link_arm_l2.STL"/>
      </geometry>
    </collision>
  </link>
  <joint name="joint_arm_l2" type="prismatic">
    <origin rpy="0 1.57655765344625E-30 -1.66533453693773E-16" xyz="0 0 0.013"/>
    <parent link="link_arm_l3"/>
    <child link="link_arm_l2"/>
    <axis xyz="0 0 1"/>
    <!-- 0.13 = 0.52/4-->
    <limit effort="100" lower="0.0" upper="0.13" velocity="1.0"/>
  </joint>
  <link name="link_arm_l1">
    <inertial>
      <origin rpy="0 0 0" xyz="-5.257E-07 -2.0482E-05 -0.096543"/>
      <mass value="0.051382"/>
      <inertia ixx="0.001" ixy="0" ixz="0" iyy="0.001" iyz="0" izz="0.001"/>
    </inertial>
    <visual>
      <origin rpy="0 0 0" xyz="0 0 0"/>
      <geometry>
        <mesh filename="meshes/link_arm_l1.STL"/>
      </geometry>
      <material name="">
        <color rgba="0.79216 0.81961 0.93333 1"/>
      </material>
    </visual>
    <collision>
      <origin rpy="0 0 0" xyz="0 0 0"/>
      <geometry>
        <mesh filename="meshes/link_arm_l1.STL"/>
      </geometry>
    </collision>
  </link>
  <joint name="joint_arm_l1" type="prismatic">
    <origin rpy="-7.63746778746202E-30 -7.88860905221012E-31 1.11022302462516E-16" xyz="0 0 0.0129999999999981"/>
    <parent link="link_arm_l2"/>
    <child link="link_arm_l1"/>
    <axis xyz="0 0 1"/>
    <!-- 0.13 = 0.52/4-->
    <limit effort="100" lower="0.0" upper="0.13" velocity="1.0"/>
  </joint>
  <link name="link_arm_l0">
    <inertial>
      <origin rpy="0 0 0" xyz="0.0270582141286185 -0.00189876414654466 -0.0377809018481181"/>
      <mass value="0.085003260946398"/>
      <inertia ixx="0.001" ixy="0" ixz="0" iyy="0.001" iyz="0" izz="0.001"/>
    </inertial>
    <visual>
      <origin rpy="0 0 0" xyz="0 0 0"/>
      <geometry>
        <mesh filename="meshes/link_arm_l0.STL"/>
      </geometry>
      <material name="">
        <color rgba="0.792156862745098 0.819607843137255 0.933333333333333 1"/>
      </material>
    </visual>
    <collision>
      <origin rpy="0 0 0" xyz="0 0 0"/>
      <geometry>
        <mesh filename="meshes/link_arm_l0.STL"/>
      </geometry>
    </collision>
  </link>
  <joint name="joint_arm_l0" type="prismatic">
    <origin rpy="7.63746778746202E-30 -3.80121128864402E-15 2.62707547767438E-15" xyz="0 0 -0.0137499999991968"/>
    <parent link="link_arm_l1"/>
    <child link="link_arm_l0"/>
    <axis xyz="0 0 1"/>
    <!-- 0.13 = 0.52/4-->
    <limit effort="100" lower="0.0" upper="0.13" velocity="1.0"/>
  </joint>
  <link name="link_wrist_yaw">
    <inertial>
      <origin rpy="0 0 0" xyz="2.20122392535771E-11 2.9317167880849E-05 -0.018966592644729"/>
      <mass value="0.0404746907425003"/>
      <inertia ixx="0.001" ixy="0" ixz="0" iyy="0.001" iyz="0" izz="0.001"/>
    </inertial>
    <visual>
      <origin rpy="0 0 0" xyz="0 0 0"/>
      <geometry>
        <mesh filename="meshes/link_wrist_yaw.STL"/>
      </geometry>
      <material name="">
        <color rgba="0.898039215686275 0.917647058823529 0.929411764705882 1"/>
      </material>
    </visual>
    <collision>
      <origin rpy="0 0 0" xyz="0 0 0"/>
      <geometry>
        <mesh filename="meshes/link_wrist_yaw.STL"/>
      </geometry>
    </collision>
  </link>
  <joint name="joint_wrist_yaw" type="revolute">
    <origin rpy="1.5708 4.2595E-14 2.6415E-15" xyz="0.0830000000000654 -0.0307500000000129 0"/>
    <parent link="link_arm_l0"/>
    <child link="link_wrist_yaw"/>
    <axis xyz="0 0 -1"/>
    <!--
      stowed to front ~225 deg: 3.15159 x 1.25 = 3.9395
      using 4.0
      stowed to back ~100 deg:  100 / 180 x 3.14159 = 1.7453
      using -1.75
    -->
    <limit effort="100" lower="-1.75" upper="4.0" velocity="1.0"/>
  </joint>
  <link name="link_head">
    <inertial>
      <origin rpy="0 0 0" xyz="0.0406850995527703 0.0396956343318414 0.0226500246461012"/>
      <mass value="0.133027236718691"/>
      <inertia ixx="0.001" ixy="0" ixz="0" iyy="0.001" iyz="0" izz="0.001"/>
    </inertial>
    <visual>
      <origin rpy="0 0 0" xyz="0 0 0"/>
      <geometry>
        <mesh filename="meshes/link_head.STL"/>
      </geometry>
      <material name="">
        <color rgba="0.792156862745098 0.819607843137255 0.933333333333333 1"/>
      </material>
    </visual>
    <collision>
      <origin rpy="0 0 0" xyz="0 0 0"/>
      <geometry>
        <mesh filename="meshes/link_head.STL"/>
      </geometry>
    </collision>
  </link>
  <joint name="joint_head" type="fixed">
    <origin rpy="1.5707963267949 -1.5707963267949 3.1416" xyz="0 1.33 0"/>
    <parent link="link_mast"/>
    <child link="link_head"/>
    <axis xyz="0 0 0"/>
  </joint>
  <link name="link_head_pan">
    <inertial>
      <origin rpy="0 0 0" xyz="-0.000326562615178591 0.00850012613776489 0.000130487222982367"/>
      <mass value="0.0273764496535409"/>
      <inertia ixx="0.001" ixy="0" ixz="0" iyy="0.001" iyz="0" izz="0.001"/>
    </inertial>
    <visual>
      <origin rpy="0 0 0" xyz="0 0 0"/>
      <geometry>
        <mesh filename="meshes/link_head_pan.STL"/>
      </geometry>
      <material name="">
        <color rgba="0.792156862745098 0.819607843137255 0.933333333333333 1"/>
      </material>
    </visual>
    <collision>
      <origin rpy="0 0 0" xyz="0 0 0"/>
      <geometry>
        <mesh filename="meshes/link_head_pan.STL"/>
      </geometry>
    </collision>
  </link>
  <joint name="joint_head_pan" type="revolute">
    <origin rpy="0 0 1.5707963267949" xyz="0.135 0.0731000000000001 -0.00319621125547975"/>
    <parent link="link_head"/>
    <child link="link_head_pan"/>
    <axis xyz="0 0 1"/>
    <!-- unconstrained range for now -->
    <limit effort="100" lower="-3.9" upper="1.5" velocity="1.0"/>
  </joint>
  <link name="link_head_tilt">
    <inertial>
      <origin rpy="0 0 0" xyz="0.00704566394917504 -0.0212256210929691 0.0302058990060359"/>
      <mass value="0.090217113313934"/>
      <inertia ixx="0.001" ixy="0" ixz="0" iyy="0.001" iyz="0" izz="0.001"/>
    </inertial>
    <visual>
      <origin rpy="0 0 0" xyz="0 0 0"/>
      <geometry>
        <mesh filename="meshes/link_head_tilt.STL"/>
      </geometry>
      <material name="">
        <color rgba="0.792156862745098 0.819607843137255 0.933333333333333 1"/>
      </material>
    </visual>
    <collision>
      <origin rpy="0 0 0" xyz="0 0 0"/>
      <geometry>
        <mesh filename="meshes/link_head_tilt.STL"/>
      </geometry>
    </collision>
  </link>
  <joint name="joint_head_tilt" type="revolute">
    <origin rpy="1.5707963267949 3.36459255518345E-15 -8.42914893687103E-17" xyz="-0.00130000001785262 0.0277624999926072 -0.0533107920897029"/>
    <parent link="link_head_pan"/>
    <child link="link_head_tilt"/>
    <axis xyz="0 0 1"/>
    <!-- unconstrained range for now -->
    <limit effort="100" lower="-1.53" upper="0.79" velocity="1.0"/>
  </joint>
  <link name="link_aruco_right_base">
    <inertial>
      <origin rpy="0 0 0" xyz="1.3878E-17 0 -0.000125"/>
      <mass value="3.59999999990368E-06"/>
      <inertia ixx="0" ixy="0" ixz="0" iyy="0" iyz="0" izz="0"/>
    </inertial>
    <visual>
      <origin rpy="0 0 0" xyz="0 0 0"/>
      <geometry>
        <mesh filename="meshes/link_aruco_right_base.STL"/>
      </geometry>
      <material name="">
        <color rgba="0.792156862745098 0.819607843137255 0.933333333333333 1"/>
      </material>
    </visual>
    <collision>
      <origin rpy="0 0 0" xyz="0 0 0"/>
      <geometry>
        <mesh filename="meshes/link_aruco_right_base.STL"/>
      </geometry>
    </collision>
  </link>
  <joint name="joint_aruco_right_base" type="fixed">
    <origin rpy="0 0 -1.5707963267949" xyz="-0.0015028 -0.1304972 0.1597482"/>
    <parent link="base_link"/>
    <child link="link_aruco_right_base"/>
    <axis xyz="0 0 0"/>
  </joint>
  <link name="link_aruco_left_base">
    <inertial>
      <origin rpy="0 0 0" xyz="2.7756E-17 0 -0.000125"/>
      <mass value="3.59999999990368E-06"/>
      <inertia ixx="0" ixy="0" ixz="0" iyy="0" iyz="0" izz="0"/>
    </inertial>
    <visual>
      <origin rpy="0 0 0" xyz="0 0 0"/>
      <geometry>
        <mesh filename="meshes/link_aruco_left_base.STL"/>
      </geometry>
      <material name="">
        <color rgba="0.792156862745098 0.819607843137255 0.933333333333333 1"/>
      </material>
    </visual>
    <collision>
      <origin rpy="0 0 0" xyz="0 0 0"/>
      <geometry>
        <mesh filename="meshes/link_aruco_left_base.STL"/>
      </geometry>
    </collision>
  </link>
  <joint name="joint_aruco_left_base" type="fixed">
    <origin rpy="0 0 -1.5707963267949" xyz="-0.00500000000000014 0.1304972 0.1597482"/>
    <parent link="base_link"/>
    <child link="link_aruco_left_base"/>
    <axis xyz="0 0 0"/>
  </joint>
  <link name="link_aruco_shoulder">
    <inertial>
      <origin rpy="0 0 0" xyz="-2.77555756156289E-17 2.56739074444567E-16 -0.000125000000000042"/>
      <mass value="0"/>
      <inertia ixx="0" ixy="0" ixz="0" iyy="0" iyz="0" izz="0"/>
    </inertial>
    <visual>
      <origin rpy="0 0 0" xyz="0 0 0"/>
      <geometry>
        <mesh filename="meshes/link_aruco_shoulder.STL"/>
      </geometry>
      <material name="">
        <color rgba="0.792156862745098 0.819607843137255 0.933333333333333 1"/>
      </material>
    </visual>
    <collision>
      <origin rpy="0 0 0" xyz="0 0 0"/>
      <geometry>
        <mesh filename="meshes/link_aruco_shoulder.STL"/>
      </geometry>
    </collision>
  </link>
  <joint name="joint_aruco_shoulder" type="fixed">
    <origin rpy="-1.53998860117704E-29 3.55962409571165E-15 0.0" xyz="-0.0133768876375287 0.0558540528812078 0.0861368272417975"/>
    <parent link="link_lift"/>
    <child link="link_aruco_shoulder"/>
    <axis xyz="0 0 0"/>
  </joint>
  <link name="link_aruco_top_wrist">
    <inertial>
      <origin rpy="0 0 0" xyz="-1.3531E-15 -3.4972E-15 -0.000125"/>
      <mass value="0"/>
      <inertia ixx="0" ixy="0" ixz="0" iyy="0" iyz="0" izz="0"/>
    </inertial>
    <visual>
      <origin rpy="0 0 0" xyz="0 0 0"/>
      <geometry>
        <mesh filename="meshes/link_aruco_top_wrist.STL"/>
      </geometry>
      <material name="">
        <color rgba="0.792156862745098 0.819607843137255 0.933333333333333 1"/>
      </material>
    </visual>
    <collision>
      <origin rpy="0 0 0" xyz="0 0 0"/>
      <geometry>
        <mesh filename="meshes/link_aruco_top_wrist.STL"/>
      </geometry>
    </collision>
  </link>
  <joint name="joint_aruco_top_wrist" type="fixed">
    <origin rpy="1.5707963267949 -8.03728587323464E-15 3.14159265358979" xyz="0.0472500000000019 0.0292850000000015 0"/>
    <parent link="link_arm_l0"/>
    <child link="link_aruco_top_wrist"/>
    <axis xyz="0 0 0"/>
  </joint>
  <link name="link_aruco_inner_wrist">
    <inertial>
      <origin rpy="0 0 0" xyz="8.32667268468867E-17 1.77635683940025E-15 -0.000125000000000264"/>
      <mass value="0"/>
      <inertia ixx="0" ixy="0" ixz="0" iyy="0" iyz="0" izz="0"/>
    </inertial>
    <visual>
      <origin rpy="0 0 0" xyz="0 0 0"/>
      <geometry>
        <mesh filename="meshes/link_aruco_inner_wrist.STL"/>
      </geometry>
      <material name="">
        <color rgba="0.792156862745098 0.819607843137255 0.933333333333333 1"/>
      </material>
    </visual>
    <collision>
      <origin rpy="0 0 0" xyz="0 0 0"/>
      <geometry>
        <mesh filename="meshes/link_aruco_inner_wrist.STL"/>
      </geometry>
    </collision>
  </link>
  <joint name="joint_aruco_inner_wrist" type="fixed">
    <origin rpy="3.14159265358979 4.23377442363088E-14 3.14159265358979" xyz="0.0472499999999947 -0.0119000000000034 -0.0272499999991938"/>
    <parent link="link_arm_l0"/>
    <child link="link_aruco_inner_wrist"/>
    <axis xyz="0 0 0"/>
  </joint>
  <material name="aluminum">
    <color rgba="0.5 0.5 0.5 1"/>
  </material>
  <material name="plastic">
    <color rgba="0.1 0.1 0.1 1"/>
  </material>
  <!-- camera body, with origin at bottom screw mount -->
  <joint name="camera_joint" type="fixed">
    <origin rpy="0.0 0.0 0.0" xyz="0.03 -0.0122 0.0182"/>
    <parent link="link_head_tilt"/>
    <child link="camera_bottom_screw_frame"/>
  </joint>
  <link name="camera_bottom_screw_frame"/>
  <joint name="camera_link_joint" type="fixed">
    <origin rpy="0 0 0" xyz="0.010600000000000002 0.0175 0.0125"/>
    <parent link="camera_bottom_screw_frame"/>
    <child link="camera_link"/>
  </joint>
  <link name="camera_link">
    <collision>
      <origin rpy="0 0 0" xyz="0 -0.0175 0"/>
      <geometry>
        <box size="0.02505 0.09 0.025"/>
      </geometry>
    </collision>
    <inertial>
      <!-- The following are not reliable values, and should not be used for modeling -->
      <mass value="0.072"/>
      <origin xyz="0 0 0"/>
      <inertia ixx="0.003881243" ixy="0.0" ixz="0.0" iyy="0.000498940" iyz="0.0" izz="0.003879257"/>
    </inertial>
  </link>
  <!-- camera depth joints and links -->
  <joint name="camera_depth_joint" type="fixed">
    <origin rpy="0 0 0" xyz="0 0 0"/>
    <parent link="camera_link"/>
    <child link="camera_depth_frame"/>
  </joint>
  <link name="camera_depth_frame"/>
  <joint name="camera_depth_optical_joint" type="fixed">
    <origin rpy="-1.5707963267948966 0 -1.5707963267948966" xyz="0 0 0"/>
    <parent link="camera_depth_frame"/>
    <child link="camera_depth_optical_frame"/>
  </joint>
  <link name="camera_depth_optical_frame"/>
  <!-- camera left IR joints and links -->
  <joint name="camera_infra1_joint" type="fixed">
    <origin rpy="0 0 0" xyz="0 0.0 0"/>
    <parent link="camera_link"/>
    <child link="camera_infra1_frame"/>
  </joint>
  <link name="camera_infra1_frame"/>
  <joint name="camera_infra1_optical_joint" type="fixed">
    <origin rpy="-1.5707963267948966 0 -1.5707963267948966" xyz="0 0 0"/>
    <parent link="camera_infra1_frame"/>
    <child link="camera_infra1_optical_frame"/>
  </joint>
  <link name="camera_infra1_optical_frame"/>
  <!-- camera right IR joints and links -->
  <joint name="camera_infra2_joint" type="fixed">
    <origin rpy="0 0 0" xyz="0 -0.05 0"/>
    <parent link="camera_link"/>
    <child link="camera_infra2_frame"/>
  </joint>
  <link name="camera_infra2_frame"/>
  <joint name="camera_infra2_optical_joint" type="fixed">
    <origin rpy="-1.5707963267948966 0 -1.5707963267948966" xyz="0 0 0"/>
    <parent link="camera_infra2_frame"/>
    <child link="camera_infra2_optical_frame"/>
  </joint>
  <link name="camera_infra2_optical_frame"/>
  <!-- camera color joints and links -->
  <joint name="camera_color_joint" type="fixed">
    <origin rpy="0 0 0" xyz="0 0.015 0"/>
    <parent link="camera_link"/>
    <child link="camera_color_frame"/>
  </joint>
  <link name="camera_color_frame"/>
  <joint name="camera_color_optical_joint" type="fixed">
    <origin rpy="-1.5707963267948966 0 -1.5707963267948966" xyz="0 0 0"/>
    <parent link="camera_color_frame"/>
    <child link="camera_color_optical_frame"/>
  </joint>
  <link name="camera_color_optical_frame"/>
  <link name="camera_accel_frame"/>
  <link name="camera_accel_optical_frame"/>
  <link name="camera_gyro_frame"/>
  <link name="camera_gyro_optical_frame"/>
  <joint name="camera_accel_joint" type="fixed">
    <origin rpy="0 0 0" xyz="-0.01174 -0.00552 0.0051"/>
    <parent link="camera_link"/>
    <child link="camera_accel_frame"/>
  </joint>
  <joint name="camera_accel_optical_joint" type="fixed">
    <origin rpy="-1.5707963267948966 0 -1.5707963267948966" xyz="0 0 0"/>
    <parent link="camera_accel_frame"/>
    <child link="camera_accel_optical_frame"/>
  </joint>
  <joint name="camera_gyro_joint" type="fixed">
    <origin rpy="0 0 0" xyz="-0.01174 -0.00552 0.0051"/>
    <parent link="camera_link"/>
    <child link="camera_gyro_frame"/>
  </joint>
  <joint name="camera_gyro_optical_joint" type="fixed">
    <origin rpy="-1.5707963267948966 0 -1.5707963267948966" xyz="0 0 0"/>
    <parent link="camera_gyro_frame"/>
    <child link="camera_gyro_optical_frame"/>
  </joint>
  <link name="laser">
    <inertial>
      <origin rpy="0 0 0" xyz="0 0 -0.000755956127492408"/>
      <mass value="0.0749979022894495"/>
      <inertia ixx="0" ixy="0" ixz="0" iyy="0" iyz="0" izz="0"/>
    </inertial>
    <visual>
      <origin rpy="0 0 0" xyz="0 0 0"/>
      <geometry>
        <mesh filename="meshes/laser.STL"/>
      </geometry>
      <material name="">
        <color rgba="0.250980392156863 0.250980392156863 0.250980392156863 1"/>
      </material>
    </visual>
    <collision>
      <origin rpy="0 0 0" xyz="0 0 0"/>
      <geometry>
        <mesh filename="meshes/laser.STL"/>
      </geometry>
    </collision>
  </link>
  <joint name="joint_laser" type="fixed">
    <origin rpy="0 0 3.1416" xyz="0.004 0 0.1664"/>
    <parent link="base_link"/>
    <child link="laser"/>
    <axis xyz="0 0 0"/>
  </joint>
  <link name="respeaker_base">
    <inertial>
      <origin rpy="0 0 0" xyz="-0.003809 -0.0023075 -0.012854"/>
      <mass value="0.015643"/>
      <inertia ixx="1.0075E-06" ixy="-5.4396E-08" ixz="-2.8652E-07" iyy="1.0569E-06" iyz="-1.8463E-07" izz="1.1947E-07"/>
    </inertial>
    <visual>
      <origin rpy="0 0 0" xyz="0 0 0"/>
      <geometry>
        <mesh filename="meshes/respeaker_base.STL"/>
      </geometry>
      <material name="">
        <color rgba="0.79216 0.81961 0.93333 1"/>
      </material>
    </visual>
    <collision>
      <origin rpy="0 0 0" xyz="0 0 0"/>
      <geometry>
        <mesh filename="meshes/respeaker_base.STL"/>
      </geometry>
    </collision>
  </link>
  <joint name="joint_respeaker" type="fixed">
    <origin rpy="-1.5707963267949 -0.698131700797725 4.93295812652799E-16" xyz="0 1.37236408874452 0.00303065898329655"/>
    <parent link="link_mast"/>
    <child link="respeaker_base"/>
    <axis xyz="0 0 0"/>
  </joint>
</robot>

