<?xml version="1.0" ?>
<robot name="human">
	<link name="base">
		<inertial>
			<origin rpy="0.00000 0.0000 0.00000" xyz="0.00000 0.00000 0.00000"/>
			<mass value="0.00010"/>
			<inertia ixx="0.00000" ixy="0" ixz="0" iyy="0.00000" iyz="0" izz="0.00000"/>
		</inertial>
	</link>
	<link name="pelvis_limb">
		<inertial>
			<origin rpy="0.00000 0.0000 0.00000" xyz="0.00000 0.00000 0.00000"/>
			<mass value="2.00000"/>
			<inertia ixx="0.00000" ixy="0" ixz="0" iyy="0.00000" iyz="0" izz="0.00000"/>
		</inertial>
		<visual>
			<origin rpy="0.00000 0.0000 0.00000" xyz="0.00000 0.00000 0.00000"/>
			<geometry>
				<mesh filename="/meshes/Pelvis.obj" scale="1.00000 1.00000 1.00000"/>
			</geometry>
			<material name="mat_0_0">
				<color rgba="0.71879 0.53909 0.35939 1.00000" />
			</material>
		</visual>
		<collision>
			<origin rpy="0.00000 0.0000 0.00000" xyz="0.00000 0.00000 0.00000"/>
			<geometry>
				<mesh filename="/meshes/Pelvis.obj" scale="1.00000 1.00000 1.00000"/>
			</geometry>
		</collision>
	</link>
	<link name="left_hip_rx">
		<inertial>
			<origin rpy="0.00000 0.0000 0.00000" xyz="0.00000 0.00000 0.00000"/>
			<mass value="0.00000"/>
			<inertia ixx="0.00000" ixy="0" ixz="0" iyy="0.00000" iyz="0" izz="0.00000"/>
		</inertial>
		<visual>
			<origin rpy="0.00000 0.0000 0.00000" xyz="0.00000 0.00000 0.00000"/>
			<geometry>
				<sphere radius="0.00000"/>
			</geometry>
			<material name="mat_1_0">
				<color rgba="0.71879 0.53909 0.35939 1.00000" />
			</material>
		</visual>
		<collision>
			<origin rpy="0.00000 0.0000 0.00000" xyz="0.00000 0.00000 0.00000"/>
			<geometry>
				<sphere radius="0.00000"/>
			</geometry>
		</collision>
	</link>
	<link name="left_hip_ry">
		<inertial>
			<origin rpy="0.00000 0.0000 0.00000" xyz="0.00000 0.00000 0.00000"/>
			<mass value="0.00000"/>
			<inertia ixx="0.00000" ixy="0" ixz="0" iyy="0.00000" iyz="0" izz="0.00000"/>
		</inertial>
		<visual>
			<origin rpy="0.00000 0.0000 0.00000" xyz="0.00000 0.00000 0.00000"/>
			<geometry>
				<sphere radius="0.00000"/>
			</geometry>
			<material name="mat_2_0">
				<color rgba="0.71879 0.53909 0.35939 1.00000" />
			</material>
		</visual>
		<collision>
			<origin rpy="0.00000 0.0000 0.00000" xyz="0.00000 0.00000 0.00000"/>
			<geometry>
				<sphere radius="0.00000"/>
			</geometry>
		</collision>
	</link>
	<link name="left_hip_rz">
		<inertial>
			<origin rpy="0.00000 0.0000 0.00000" xyz="0.00000 0.00000 0.00000"/>
			<mass value="0.00000"/>
			<inertia ixx="0.00000" ixy="0" ixz="0" iyy="0.00000" iyz="0" izz="0.00000"/>
		</inertial>
		<visual>
			<origin rpy="0.00000 0.0000 0.00000" xyz="0.00000 0.00000 0.00000"/>
			<geometry>
				<sphere radius="0.00000"/>
			</geometry>
			<material name="mat_3_0">
				<color rgba="0.71879 0.53909 0.35939 1.00000" />
			</material>
		</visual>
		<collision>
			<origin rpy="0.00000 0.0000 0.00000" xyz="0.00000 0.00000 0.00000"/>
			<geometry>
				<sphere radius="0.00000"/>
			</geometry>
		</collision>
	</link>
	<link name="left_hip_limb">
		<inertial>
			<origin rpy="0.00000 0.0000 0.00000" xyz="0.00000 0.00000 0.00000"/>
			<mass value="2.00000"/>
			<inertia ixx="0.00000" ixy="0" ixz="0" iyy="0.00000" iyz="0" izz="0.00000"/>
		</inertial>
		<visual>
			<origin rpy="0.00000 0.0000 0.00000" xyz="0.00000 0.00000 0.00000"/>
			<geometry>
				<mesh filename="/meshes/L_Hip.obj" scale="1.00000 1.00000 1.00000"/>
			</geometry>
			<material name="mat_4_0">
				<color rgba="0.71879 0.53909 0.35939 1.00000" />
			</material>
		</visual>
		<collision>
			<origin rpy="0.00000 0.0000 0.00000" xyz="0.00000 0.00000 0.00000"/>
			<geometry>
				<mesh filename="/meshes/L_Hip.obj" scale="1.00000 1.00000 1.00000"/>
			</geometry>
		</collision>
	</link>
	<link name="left_knee_rx">
		<inertial>
			<origin rpy="0.00000 0.0000 0.00000" xyz="0.00000 0.00000 0.00000"/>
			<mass value="0.00000"/>
			<inertia ixx="0.00000" ixy="0" ixz="0" iyy="0.00000" iyz="0" izz="0.00000"/>
		</inertial>
		<visual>
			<origin rpy="0.00000 0.0000 0.00000" xyz="0.00000 0.00000 0.00000"/>
			<geometry>
				<sphere radius="0.00000"/>
			</geometry>
			<material name="mat_5_0">
				<color rgba="0.71879 0.53909 0.35939 1.00000" />
			</material>
		</visual>
		<collision>
			<origin rpy="0.00000 0.0000 0.00000" xyz="0.00000 0.00000 0.00000"/>
			<geometry>
				<sphere radius="0.00000"/>
			</geometry>
		</collision>
	</link>
	<link name="left_knee_ry">
		<inertial>
			<origin rpy="0.00000 0.0000 0.00000" xyz="0.00000 0.00000 0.00000"/>
			<mass value="0.00000"/>
			<inertia ixx="0.00000" ixy="0" ixz="0" iyy="0.00000" iyz="0" izz="0.00000"/>
		</inertial>
		<visual>
			<origin rpy="0.00000 0.0000 0.00000" xyz="0.00000 0.00000 0.00000"/>
			<geometry>
				<sphere radius="0.00000"/>
			</geometry>
			<material name="mat_6_0">
				<color rgba="0.71879 0.53909 0.35939 1.00000" />
			</material>
		</visual>
		<collision>
			<origin rpy="0.00000 0.0000 0.00000" xyz="0.00000 0.00000 0.00000"/>
			<geometry>
				<sphere radius="0.00000"/>
			</geometry>
		</collision>
	</link>
	<link name="left_knee_rz">
		<inertial>
			<origin rpy="0.00000 0.0000 0.00000" xyz="0.00000 0.00000 0.00000"/>
			<mass value="0.00000"/>
			<inertia ixx="0.00000" ixy="0" ixz="0" iyy="0.00000" iyz="0" izz="0.00000"/>
		</inertial>
		<visual>
			<origin rpy="0.00000 0.0000 0.00000" xyz="0.00000 0.00000 0.00000"/>
			<geometry>
				<sphere radius="0.00000"/>
			</geometry>
			<material name="mat_7_0">
				<color rgba="0.71879 0.53909 0.35939 1.00000" />
			</material>
		</visual>
		<collision>
			<origin rpy="0.00000 0.0000 0.00000" xyz="0.00000 0.00000 0.00000"/>
			<geometry>
				<sphere radius="0.00000"/>
			</geometry>
		</collision>
	</link>
	<link name="left_knee_limb">
		<inertial>
			<origin rpy="0.00000 0.0000 0.00000" xyz="0.00000 0.00000 0.00000"/>
			<mass value="2.00000"/>
			<inertia ixx="0.03487" ixy="0" ixz="0" iyy="0.00791" iyz="0" izz="0.03324"/>
		</inertial>
		<visual>
			<origin rpy="0.00000 0.0000 0.00000" xyz="0.00000 0.00000 0.00000"/>
			<geometry>
				<mesh filename="/meshes/L_Knee.obj" scale="1.00000 1.00000 1.00000"/>
			</geometry>
			<material name="mat_8_0">
				<color rgba="0.71879 0.53909 0.35939 1.00000" />
			</material>
		</visual>
		<collision>
			<origin rpy="0.00000 0.0000 0.00000" xyz="0.00000 0.00000 0.00000"/>
			<geometry>
				<mesh filename="/meshes/L_Knee.obj" scale="1.00000 1.00000 1.00000"/>
			</geometry>
		</collision>
	</link>
	<link name="left_ankle_rx">
		<inertial>
			<origin rpy="0.00000 0.0000 0.00000" xyz="0.00000 0.00000 0.00000"/>
			<mass value="0.00000"/>
			<inertia ixx="0.00000" ixy="0" ixz="0" iyy="0.00000" iyz="0" izz="0.00000"/>
		</inertial>
		<visual>
			<origin rpy="0.00000 0.0000 0.00000" xyz="0.00000 0.00000 0.00000"/>
			<geometry>
				<sphere radius="0.00000"/>
			</geometry>
			<material name="mat_9_0">
				<color rgba="0.71879 0.53909 0.35939 1.00000" />
			</material>
		</visual>
		<collision>
			<origin rpy="0.00000 0.0000 0.00000" xyz="0.00000 0.00000 0.00000"/>
			<geometry>
				<sphere radius="0.00000"/>
			</geometry>
		</collision>
	</link>
	<link name="left_ankle_ry">
		<inertial>
			<origin rpy="0.00000 0.0000 0.00000" xyz="0.00000 0.00000 0.00000"/>
			<mass value="0.00000"/>
			<inertia ixx="0.00000" ixy="0" ixz="0" iyy="0.00000" iyz="0" izz="0.00000"/>
		</inertial>
		<visual>
			<origin rpy="0.00000 0.0000 0.00000" xyz="0.00000 0.00000 0.00000"/>
			<geometry>
				<sphere radius="0.00000"/>
			</geometry>
			<material name="mat_10_0">
				<color rgba="0.71879 0.53909 0.35939 1.00000" />
			</material>
		</visual>
		<collision>
			<origin rpy="0.00000 0.0000 0.00000" xyz="0.00000 0.00000 0.00000"/>
			<geometry>
				<sphere radius="0.00000"/>
			</geometry>
		</collision>
	</link>
	<link name="left_ankle_rz">
		<inertial>
			<origin rpy="0.00000 0.0000 0.00000" xyz="0.00000 0.00000 0.00000"/>
			<mass value="0.00000"/>
			<inertia ixx="0.00000" ixy="0" ixz="0" iyy="0.00000" iyz="0" izz="0.00000"/>
		</inertial>
		<visual>
			<origin rpy="0.00000 0.0000 0.00000" xyz="0.00000 0.00000 0.00000"/>
			<geometry>
				<sphere radius="0.00000"/>
			</geometry>
			<material name="mat_11_0">
				<color rgba="0.71879 0.53909 0.35939 1.00000" />
			</material>
		</visual>
		<collision>
			<origin rpy="0.00000 0.0000 0.00000" xyz="0.00000 0.00000 0.00000"/>
			<geometry>
				<sphere radius="0.00000"/>
			</geometry>
		</collision>
	</link>
	<link name="left_ankle_limb">
		<inertial>
			<origin rpy="0.00000 0.0000 0.00000" xyz="0.00000 0.00000 0.00000"/>
			<mass value="2.00000"/>
			<inertia ixx="0.00736" ixy="0" ixz="0" iyy="0.00763" iyz="0" izz="0.00377"/>
		</inertial>
		<visual>
			<origin rpy="0.00000 0.0000 0.00000" xyz="0.00000 0.00000 0.00000"/>
			<geometry>
				<mesh filename="/meshes/L_Ankle.obj" scale="1.00000 1.00000 1.00000"/>
			</geometry>
			<material name="mat_12_0">
				<color rgba="0.71879 0.53909 0.35939 1.00000" />
			</material>
		</visual>
		<collision>
			<origin rpy="0.00000 0.0000 0.00000" xyz="0.00000 0.00000 0.00000"/>
			<geometry>
				<mesh filename="/meshes/L_Ankle.obj" scale="1.00000 1.00000 1.00000"/>
			</geometry>
		</collision>
	</link>
	<link name="left_foot_rx">
		<inertial>
			<origin rpy="0.00000 0.0000 0.00000" xyz="0.00000 0.00000 0.00000"/>
			<mass value="0.00000"/>
			<inertia ixx="0.00000" ixy="0" ixz="0" iyy="0.00000" iyz="0" izz="0.00000"/>
		</inertial>
		<visual>
			<origin rpy="0.00000 0.0000 0.00000" xyz="0.00000 0.00000 0.00000"/>
			<geometry>
				<sphere radius="0.00000"/>
			</geometry>
			<material name="mat_13_0">
				<color rgba="0.71879 0.53909 0.35939 1.00000" />
			</material>
		</visual>
		<collision>
			<origin rpy="0.00000 0.0000 0.00000" xyz="0.00000 0.00000 0.00000"/>
			<geometry>
				<sphere radius="0.00000"/>
			</geometry>
		</collision>
	</link>
	<link name="left_foot_ry">
		<inertial>
			<origin rpy="0.00000 0.0000 0.00000" xyz="0.00000 0.00000 0.00000"/>
			<mass value="0.00000"/>
			<inertia ixx="0.00000" ixy="0" ixz="0" iyy="0.00000" iyz="0" izz="0.00000"/>
		</inertial>
		<visual>
			<origin rpy="0.00000 0.0000 0.00000" xyz="0.00000 0.00000 0.00000"/>
			<geometry>
				<sphere radius="0.00000"/>
			</geometry>
			<material name="mat_14_0">
				<color rgba="0.71879 0.53909 0.35939 1.00000" />
			</material>
		</visual>
		<collision>
			<origin rpy="0.00000 0.0000 0.00000" xyz="0.00000 0.00000 0.00000"/>
			<geometry>
				<sphere radius="0.00000"/>
			</geometry>
		</collision>
	</link>
	<link name="left_foot_rz">
		<inertial>
			<origin rpy="0.00000 0.0000 0.00000" xyz="0.00000 0.00000 0.00000"/>
			<mass value="0.00000"/>
			<inertia ixx="0.00000" ixy="0" ixz="0" iyy="0.00000" iyz="0" izz="0.00000"/>
		</inertial>
		<visual>
			<origin rpy="0.00000 0.0000 0.00000" xyz="0.00000 0.00000 0.00000"/>
			<geometry>
				<sphere radius="0.00000"/>
			</geometry>
			<material name="mat_15_0">
				<color rgba="0.71879 0.53909 0.35939 1.00000" />
			</material>
		</visual>
		<collision>
			<origin rpy="0.00000 0.0000 0.00000" xyz="0.00000 0.00000 0.00000"/>
			<geometry>
				<sphere radius="0.00000"/>
			</geometry>
		</collision>
	</link>
	<link name="left_foot_limb">
		<inertial>
			<origin rpy="0.00000 0.0000 0.00000" xyz="0.00000 0.00000 0.00000"/>
			<mass value="2.00000"/>
			<inertia ixx="0.00118" ixy="0" ixz="0" iyy="0.00193" iyz="0" izz="0.00113"/>
		</inertial>
		<visual>
			<origin rpy="0.00000 0.0000 0.00000" xyz="0.00000 0.00000 0.00000"/>
			<geometry>
				<mesh filename="/meshes/L_Foot.obj" scale="1.00000 1.00000 1.00000"/>
			</geometry>
			<material name="mat_16_0">
				<color rgba="0.71879 0.53909 0.35939 1.00000" />
			</material>
		</visual>
		<collision>
			<origin rpy="0.00000 0.0000 0.00000" xyz="0.00000 0.00000 0.00000"/>
			<geometry>
				<mesh filename="/meshes/L_Foot.obj" scale="1.00000 1.00000 1.00000"/>
			</geometry>
		</collision>
	</link>
	<link name="right_hip_rx">
		<inertial>
			<origin rpy="0.00000 0.0000 0.00000" xyz="0.00000 0.00000 0.00000"/>
			<mass value="0.00000"/>
			<inertia ixx="0.00000" ixy="0" ixz="0" iyy="0.00000" iyz="0" izz="0.00000"/>
		</inertial>
		<visual>
			<origin rpy="0.00000 0.0000 0.00000" xyz="0.00000 0.00000 0.00000"/>
			<geometry>
				<sphere radius="0.00000"/>
			</geometry>
			<material name="mat_19_0">
				<color rgba="0.71879 0.53909 0.35939 1.00000" />
			</material>
		</visual>
		<collision>
			<origin rpy="0.00000 0.0000 0.00000" xyz="0.00000 0.00000 0.00000"/>
			<geometry>
				<sphere radius="0.00000"/>
			</geometry>
		</collision>
	</link>
	<link name="right_hip_ry">
		<inertial>
			<origin rpy="0.00000 0.0000 0.00000" xyz="0.00000 0.00000 0.00000"/>
			<mass value="0.00000"/>
			<inertia ixx="0.00000" ixy="0" ixz="0" iyy="0.00000" iyz="0" izz="0.00000"/>
		</inertial>
		<visual>
			<origin rpy="0.00000 0.0000 0.00000" xyz="0.00000 0.00000 0.00000"/>
			<geometry>
				<sphere radius="0.00000"/>
			</geometry>
			<material name="mat_20_0">
				<color rgba="0.71879 0.53909 0.35939 1.00000" />
			</material>
		</visual>
		<collision>
			<origin rpy="0.00000 0.0000 0.00000" xyz="0.00000 0.00000 0.00000"/>
			<geometry>
				<sphere radius="0.00000"/>
			</geometry>
		</collision>
	</link>
	<link name="right_hip_rz">
		<inertial>
			<origin rpy="0.00000 0.0000 0.00000" xyz="0.00000 0.00000 0.00000"/>
			<mass value="0.00000"/>
			<inertia ixx="0.00000" ixy="0" ixz="0" iyy="0.00000" iyz="0" izz="0.00000"/>
		</inertial>
		<visual>
			<origin rpy="0.00000 0.0000 0.00000" xyz="0.00000 0.00000 0.00000"/>
			<geometry>
				<sphere radius="0.00000"/>
			</geometry>
			<material name="mat_21_0">
				<color rgba="0.71879 0.53909 0.35939 1.00000" />
			</material>
		</visual>
		<collision>
			<origin rpy="0.00000 0.0000 0.00000" xyz="0.00000 0.00000 0.00000"/>
			<geometry>
				<sphere radius="0.00000"/>
			</geometry>
		</collision>
	</link>
	<link name="right_hip_limb">
		<inertial>
			<origin rpy="0.00000 0.0000 0.00000" xyz="0.00000 0.00000 0.00000"/>
			<mass value="2.00000"/>
			<inertia ixx="0.00000" ixy="0" ixz="0" iyy="0.00000" iyz="0" izz="0.00000"/>
		</inertial>
		<visual>
			<origin rpy="0.00000 0.0000 0.00000" xyz="0.00000 0.00000 0.00000"/>
			<geometry>
				<mesh filename="/meshes/R_Hip.obj" scale="1.00000 1.00000 1.00000"/>
			</geometry>
			<material name="mat_22_0">
				<color rgba="0.71879 0.53909 0.35939 1.00000" />
			</material>
		</visual>
		<collision>
			<origin rpy="0.00000 0.0000 0.00000" xyz="0.00000 0.00000 0.00000"/>
			<geometry>
				<mesh filename="/meshes/R_Hip.obj" scale="1.00000 1.00000 1.00000"/>
			</geometry>
		</collision>
	</link>
	<link name="right_knee_rx">
		<inertial>
			<origin rpy="0.00000 0.0000 0.00000" xyz="0.00000 0.00000 0.00000"/>
			<mass value="0.00000"/>
			<inertia ixx="0.00000" ixy="0" ixz="0" iyy="0.00000" iyz="0" izz="0.00000"/>
		</inertial>
		<visual>
			<origin rpy="0.00000 0.0000 0.00000" xyz="0.00000 0.00000 0.00000"/>
			<geometry>
				<sphere radius="0.00000"/>
			</geometry>
			<material name="mat_23_0">
				<color rgba="0.71879 0.53909 0.35939 1.00000" />
			</material>
		</visual>
		<collision>
			<origin rpy="0.00000 0.0000 0.00000" xyz="0.00000 0.00000 0.00000"/>
			<geometry>
				<sphere radius="0.00000"/>
			</geometry>
		</collision>
	</link>
	<link name="right_knee_ry">
		<inertial>
			<origin rpy="0.00000 0.0000 0.00000" xyz="0.00000 0.00000 0.00000"/>
			<mass value="0.00000"/>
			<inertia ixx="0.00000" ixy="0" ixz="0" iyy="0.00000" iyz="0" izz="0.00000"/>
		</inertial>
		<visual>
			<origin rpy="0.00000 0.0000 0.00000" xyz="0.00000 0.00000 0.00000"/>
			<geometry>
				<sphere radius="0.00000"/>
			</geometry>
			<material name="mat_24_0">
				<color rgba="0.71879 0.53909 0.35939 1.00000" />
			</material>
		</visual>
		<collision>
			<origin rpy="0.00000 0.0000 0.00000" xyz="0.00000 0.00000 0.00000"/>
			<geometry>
				<sphere radius="0.00000"/>
			</geometry>
		</collision>
	</link>
	<link name="right_knee_rz">
		<inertial>
			<origin rpy="0.00000 0.0000 0.00000" xyz="0.00000 0.00000 0.00000"/>
			<mass value="0.00000"/>
			<inertia ixx="0.00000" ixy="0" ixz="0" iyy="0.00000" iyz="0" izz="0.00000"/>
		</inertial>
		<visual>
			<origin rpy="0.00000 0.0000 0.00000" xyz="0.00000 0.00000 0.00000"/>
			<geometry>
				<sphere radius="0.00000"/>
			</geometry>
			<material name="mat_25_0">
				<color rgba="0.71879 0.53909 0.35939 1.00000" />
			</material>
		</visual>
		<collision>
			<origin rpy="0.00000 0.0000 0.00000" xyz="0.00000 0.00000 0.00000"/>
			<geometry>
				<sphere radius="0.00000"/>
			</geometry>
		</collision>
	</link>
	<link name="right_knee_limb">
		<inertial>
			<origin rpy="0.00000 0.0000 0.00000" xyz="0.00000 0.00000 0.00000"/>
			<mass value="2.00000"/>
			<inertia ixx="0.03468" ixy="0" ixz="0" iyy="0.00776" iyz="0" izz="0.03330"/>
		</inertial>
		<visual>
			<origin rpy="0.00000 0.0000 0.00000" xyz="0.00000 0.00000 0.00000"/>
			<geometry>
				<mesh filename="/meshes/R_Knee.obj" scale="1.00000 1.00000 1.00000"/>
			</geometry>
			<material name="mat_26_0">
				<color rgba="0.71879 0.53909 0.35939 1.00000" />
			</material>
		</visual>
		<collision>
			<origin rpy="0.00000 0.0000 0.00000" xyz="0.00000 0.00000 0.00000"/>
			<geometry>
				<mesh filename="/meshes/R_Knee.obj" scale="1.00000 1.00000 1.00000"/>
			</geometry>
		</collision>
	</link>
	<link name="right_ankle_rx">
		<inertial>
			<origin rpy="0.00000 0.0000 0.00000" xyz="0.00000 0.00000 0.00000"/>
			<mass value="0.00000"/>
			<inertia ixx="0.00000" ixy="0" ixz="0" iyy="0.00000" iyz="0" izz="0.00000"/>
		</inertial>
		<visual>
			<origin rpy="0.00000 0.0000 0.00000" xyz="0.00000 0.00000 0.00000"/>
			<geometry>
				<sphere radius="0.00000"/>
			</geometry>
			<material name="mat_27_0">
				<color rgba="0.71879 0.53909 0.35939 1.00000" />
			</material>
		</visual>
		<collision>
			<origin rpy="0.00000 0.0000 0.00000" xyz="0.00000 0.00000 0.00000"/>
			<geometry>
				<sphere radius="0.00000"/>
			</geometry>
		</collision>
	</link>
	<link name="right_ankle_ry">
		<inertial>
			<origin rpy="0.00000 0.0000 0.00000" xyz="0.00000 0.00000 0.00000"/>
			<mass value="0.00000"/>
			<inertia ixx="0.00000" ixy="0" ixz="0" iyy="0.00000" iyz="0" izz="0.00000"/>
		</inertial>
		<visual>
			<origin rpy="0.00000 0.0000 0.00000" xyz="0.00000 0.00000 0.00000"/>
			<geometry>
				<sphere radius="0.00000"/>
			</geometry>
			<material name="mat_28_0">
				<color rgba="0.71879 0.53909 0.35939 1.00000" />
			</material>
		</visual>
		<collision>
			<origin rpy="0.00000 0.0000 0.00000" xyz="0.00000 0.00000 0.00000"/>
			<geometry>
				<sphere radius="0.00000"/>
			</geometry>
		</collision>
	</link>
	<link name="right_ankle_rz">
		<inertial>
			<origin rpy="0.00000 0.0000 0.00000" xyz="0.00000 0.00000 0.00000"/>
			<mass value="0.00000"/>
			<inertia ixx="0.00000" ixy="0" ixz="0" iyy="0.00000" iyz="0" izz="0.00000"/>
		</inertial>
		<visual>
			<origin rpy="0.00000 0.0000 0.00000" xyz="0.00000 0.00000 0.00000"/>
			<geometry>
				<sphere radius="0.00000"/>
			</geometry>
			<material name="mat_29_0">
				<color rgba="0.71879 0.53909 0.35939 1.00000" />
			</material>
		</visual>
		<collision>
			<origin rpy="0.00000 0.0000 0.00000" xyz="0.00000 0.00000 0.00000"/>
			<geometry>
				<sphere radius="0.00000"/>
			</geometry>
		</collision>
	</link>
	<link name="right_ankle_limb">
		<inertial>
			<origin rpy="0.00000 0.0000 0.00000" xyz="0.00000 0.00000 0.00000"/>
			<mass value="2.00000"/>
			<inertia ixx="0.00777" ixy="0" ixz="0" iyy="0.00782" iyz="0" izz="0.00385"/>
		</inertial>
		<visual>
			<origin rpy="0.00000 0.0000 0.00000" xyz="0.00000 0.00000 0.00000"/>
			<geometry>
				<mesh filename="/meshes/R_Ankle.obj" scale="1.00000 1.00000 1.00000"/>
			</geometry>
			<material name="mat_30_0">
				<color rgba="0.71879 0.53909 0.35939 1.00000" />
			</material>
		</visual>
		<collision>
			<origin rpy="0.00000 0.0000 0.00000" xyz="0.00000 0.00000 0.00000"/>
			<geometry>
				<mesh filename="/meshes/R_Ankle.obj" scale="1.00000 1.00000 1.00000"/>
			</geometry>
		</collision>
	</link>
	<link name="right_foot_rx">
		<inertial>
			<origin rpy="0.00000 0.0000 0.00000" xyz="0.00000 0.00000 0.00000"/>
			<mass value="0.00000"/>
			<inertia ixx="0.00000" ixy="0" ixz="0" iyy="0.00000" iyz="0" izz="0.00000"/>
		</inertial>
		<visual>
			<origin rpy="0.00000 0.0000 0.00000" xyz="0.00000 0.00000 0.00000"/>
			<geometry>
				<sphere radius="0.00000"/>
			</geometry>
			<material name="mat_31_0">
				<color rgba="0.71879 0.53909 0.35939 1.00000" />
			</material>
		</visual>
		<collision>
			<origin rpy="0.00000 0.0000 0.00000" xyz="0.00000 0.00000 0.00000"/>
			<geometry>
				<sphere radius="0.00000"/>
			</geometry>
		</collision>
	</link>
	<link name="right_foot_ry">
		<inertial>
			<origin rpy="0.00000 0.0000 0.00000" xyz="0.00000 0.00000 0.00000"/>
			<mass value="0.00000"/>
			<inertia ixx="0.00000" ixy="0" ixz="0" iyy="0.00000" iyz="0" izz="0.00000"/>
		</inertial>
		<visual>
			<origin rpy="0.00000 0.0000 0.00000" xyz="0.00000 0.00000 0.00000"/>
			<geometry>
				<sphere radius="0.00000"/>
			</geometry>
			<material name="mat_32_0">
				<color rgba="0.71879 0.53909 0.35939 1.00000" />
			</material>
		</visual>
		<collision>
			<origin rpy="0.00000 0.0000 0.00000" xyz="0.00000 0.00000 0.00000"/>
			<geometry>
				<sphere radius="0.00000"/>
			</geometry>
		</collision>
	</link>
	<link name="right_foot_rz">
		<inertial>
			<origin rpy="0.00000 0.0000 0.00000" xyz="0.00000 0.00000 0.00000"/>
			<mass value="0.00000"/>
			<inertia ixx="0.00000" ixy="0" ixz="0" iyy="0.00000" iyz="0" izz="0.00000"/>
		</inertial>
		<visual>
			<origin rpy="0.00000 0.0000 0.00000" xyz="0.00000 0.00000 0.00000"/>
			<geometry>
				<sphere radius="0.00000"/>
			</geometry>
			<material name="mat_33_0">
				<color rgba="0.71879 0.53909 0.35939 1.00000" />
			</material>
		</visual>
		<collision>
			<origin rpy="0.00000 0.0000 0.00000" xyz="0.00000 0.00000 0.00000"/>
			<geometry>
				<sphere radius="0.00000"/>
			</geometry>
		</collision>
	</link>
	<link name="right_foot_limb">
		<inertial>
			<origin rpy="0.00000 0.0000 0.00000" xyz="0.00000 0.00000 0.00000"/>
			<mass value="2.00000"/>
			<inertia ixx="0.00122" ixy="0" ixz="0" iyy="0.00197" iyz="0" izz="0.00116"/>
		</inertial>
		<visual>
			<origin rpy="0.00000 0.0000 0.00000" xyz="0.00000 0.00000 0.00000"/>
			<geometry>
				<mesh filename="/meshes/R_Foot.obj" scale="1.00000 1.00000 1.00000"/>
			</geometry>
			<material name="mat_34_0">
				<color rgba="0.71879 0.53909 0.35939 1.00000" />
			</material>
		</visual>
		<collision>
			<origin rpy="0.00000 0.0000 0.00000" xyz="0.00000 0.00000 0.00000"/>
			<geometry>
				<mesh filename="/meshes/R_Foot.obj" scale="1.00000 1.00000 1.00000"/>
			</geometry>
		</collision>
	</link>
	<link name="spine_2_rx">
		<inertial>
			<origin rpy="0.00000 0.0000 0.00000" xyz="0.00000 0.00000 0.00000"/>
			<mass value="0.00000"/>
			<inertia ixx="0.00000" ixy="0" ixz="0" iyy="0.00000" iyz="0" izz="0.00000"/>
		</inertial>
		<visual>
			<origin rpy="0.00000 0.0000 0.00000" xyz="0.00000 0.00000 0.00000"/>
			<geometry>
				<sphere radius="0.00000"/>
			</geometry>
			<material name="mat_37_0">
				<color rgba="0.71879 0.53909 0.35939 1.00000" />
			</material>
		</visual>
		<collision>
			<origin rpy="0.00000 0.0000 0.00000" xyz="0.00000 0.00000 0.00000"/>
			<geometry>
				<sphere radius="0.00000"/>
			</geometry>
		</collision>
	</link>
	<link name="spine_2_ry">
		<inertial>
			<origin rpy="0.00000 0.0000 0.00000" xyz="0.00000 0.00000 0.00000"/>
			<mass value="0.00000"/>
			<inertia ixx="0.00000" ixy="0" ixz="0" iyy="0.00000" iyz="0" izz="0.00000"/>
		</inertial>
		<visual>
			<origin rpy="0.00000 0.0000 0.00000" xyz="0.00000 0.00000 0.00000"/>
			<geometry>
				<sphere radius="0.00000"/>
			</geometry>
			<material name="mat_38_0">
				<color rgba="0.71879 0.53909 0.35939 1.00000" />
			</material>
		</visual>
		<collision>
			<origin rpy="0.00000 0.0000 0.00000" xyz="0.00000 0.00000 0.00000"/>
			<geometry>
				<sphere radius="0.00000"/>
			</geometry>
		</collision>
	</link>
	<link name="spine_2_rz">
		<inertial>
			<origin rpy="0.00000 0.0000 0.00000" xyz="0.00000 0.00000 0.00000"/>
			<mass value="0.00000"/>
			<inertia ixx="0.00000" ixy="0" ixz="0" iyy="0.00000" iyz="0" izz="0.00000"/>
		</inertial>
		<visual>
			<origin rpy="0.00000 0.0000 0.00000" xyz="0.00000 0.00000 0.00000"/>
			<geometry>
				<sphere radius="0.00000"/>
			</geometry>
			<material name="mat_39_0">
				<color rgba="0.71879 0.53909 0.35939 1.00000" />
			</material>
		</visual>
		<collision>
			<origin rpy="0.00000 0.0000 0.00000" xyz="0.00000 0.00000 0.00000"/>
			<geometry>
				<sphere radius="0.00000"/>
			</geometry>
		</collision>
	</link>
	<link name="spine_2_limb">
		<inertial>
			<origin rpy="0.00000 0.0000 0.00000" xyz="0.00000 0.00000 0.00000"/>
			<mass value="2.00000"/>
			<inertia ixx="0.01821" ixy="0" ixz="0" iyy="0.03264" iyz="0" izz="0.02330"/>
		</inertial>
		<visual>
			<origin rpy="0.00000 0.0000 0.00000" xyz="0.00000 0.00000 0.00000"/>
			<geometry>
				<mesh filename="/meshes/Spine1.obj" scale="1.00000 1.00000 1.00000"/>
			</geometry>
			<material name="mat_40_0">
				<color rgba="0.71879 0.53909 0.35939 1.00000" />
			</material>
		</visual>
		<collision>
			<origin rpy="0.00000 0.0000 0.00000" xyz="0.00000 0.00000 0.00000"/>
			<geometry>
				<mesh filename="/meshes/Spine1.obj" scale="1.00000 1.00000 1.00000"/>
			</geometry>
		</collision>
	</link>
	<link name="spine_3_rx">
		<inertial>
			<origin rpy="0.00000 0.0000 0.00000" xyz="0.00000 0.00000 0.00000"/>
			<mass value="0.00000"/>
			<inertia ixx="0.00000" ixy="0" ixz="0" iyy="0.00000" iyz="0" izz="0.00000"/>
		</inertial>
		<visual>
			<origin rpy="0.00000 0.0000 0.00000" xyz="0.00000 0.00000 0.00000"/>
			<geometry>
				<sphere radius="0.00000"/>
			</geometry>
			<material name="mat_41_0">
				<color rgba="0.71879 0.53909 0.35939 1.00000" />
			</material>
		</visual>
		<collision>
			<origin rpy="0.00000 0.0000 0.00000" xyz="0.00000 0.00000 0.00000"/>
			<geometry>
				<sphere radius="0.00000"/>
			</geometry>
		</collision>
	</link>
	<link name="spine_3_ry">
		<inertial>
			<origin rpy="0.00000 0.0000 0.00000" xyz="0.00000 0.00000 0.00000"/>
			<mass value="0.00000"/>
			<inertia ixx="0.00000" ixy="0" ixz="0" iyy="0.00000" iyz="0" izz="0.00000"/>
		</inertial>
		<visual>
			<origin rpy="0.00000 0.0000 0.00000" xyz="0.00000 0.00000 0.00000"/>
			<geometry>
				<sphere radius="0.00000"/>
			</geometry>
			<material name="mat_42_0">
				<color rgba="0.71879 0.53909 0.35939 1.00000" />
			</material>
		</visual>
		<collision>
			<origin rpy="0.00000 0.0000 0.00000" xyz="0.00000 0.00000 0.00000"/>
			<geometry>
				<sphere radius="0.00000"/>
			</geometry>
		</collision>
	</link>
	<link name="spine_3_rz">
		<inertial>
			<origin rpy="0.00000 0.0000 0.00000" xyz="0.00000 0.00000 0.00000"/>
			<mass value="0.00000"/>
			<inertia ixx="0.00000" ixy="0" ixz="0" iyy="0.00000" iyz="0" izz="0.00000"/>
		</inertial>
		<visual>
			<origin rpy="0.00000 0.0000 0.00000" xyz="0.00000 0.00000 0.00000"/>
			<geometry>
				<sphere radius="0.00000"/>
			</geometry>
			<material name="mat_43_0">
				<color rgba="0.71879 0.53909 0.35939 1.00000" />
			</material>
		</visual>
		<collision>
			<origin rpy="0.00000 0.0000 0.00000" xyz="0.00000 0.00000 0.00000"/>
			<geometry>
				<sphere radius="0.00000"/>
			</geometry>
		</collision>
	</link>
	<link name="spine_3_limb">
		<inertial>
			<origin rpy="0.00000 0.0000 0.00000" xyz="0.00000 0.00000 0.00000"/>
			<mass value="2.00000"/>
			<inertia ixx="0.01582" ixy="0" ixz="0" iyy="0.03312" iyz="0" izz="0.02315"/>
		</inertial>
		<visual>
			<origin rpy="0.00000 0.0000 0.00000" xyz="0.00000 0.00000 0.00000"/>
			<geometry>
				<mesh filename="/meshes/Spine2.obj" scale="1.00000 1.00000 1.00000"/>
			</geometry>
			<material name="mat_44_0">
				<color rgba="0.71879 0.53909 0.35939 1.00000" />
			</material>
		</visual>
		<collision>
			<origin rpy="0.00000 0.0000 0.00000" xyz="0.00000 0.00000 0.00000"/>
			<geometry>
				<mesh filename="/meshes/Spine2.obj" scale="1.00000 1.00000 1.00000"/>
			</geometry>
		</collision>
	</link>
	<link name="spine_4_rx">
		<inertial>
			<origin rpy="0.00000 0.0000 0.00000" xyz="0.00000 0.00000 0.00000"/>
			<mass value="0.00000"/>
			<inertia ixx="0.00000" ixy="0" ixz="0" iyy="0.00000" iyz="0" izz="0.00000"/>
		</inertial>
		<visual>
			<origin rpy="0.00000 0.0000 0.00000" xyz="0.00000 0.00000 0.00000"/>
			<geometry>
				<sphere radius="0.00000"/>
			</geometry>
			<material name="mat_45_0">
				<color rgba="0.71879 0.53909 0.35939 1.00000" />
			</material>
		</visual>
		<collision>
			<origin rpy="0.00000 0.0000 0.00000" xyz="0.00000 0.00000 0.00000"/>
			<geometry>
				<sphere radius="0.00000"/>
			</geometry>
		</collision>
	</link>
	<link name="spine_4_ry">
		<inertial>
			<origin rpy="0.00000 0.0000 0.00000" xyz="0.00000 0.00000 0.00000"/>
			<mass value="0.00000"/>
			<inertia ixx="0.00000" ixy="0" ixz="0" iyy="0.00000" iyz="0" izz="0.00000"/>
		</inertial>
		<visual>
			<origin rpy="0.00000 0.0000 0.00000" xyz="0.00000 0.00000 0.00000"/>
			<geometry>
				<sphere radius="0.00000"/>
			</geometry>
			<material name="mat_46_0">
				<color rgba="0.71879 0.53909 0.35939 1.00000" />
			</material>
		</visual>
		<collision>
			<origin rpy="0.00000 0.0000 0.00000" xyz="0.00000 0.00000 0.00000"/>
			<geometry>
				<sphere radius="0.00000"/>
			</geometry>
		</collision>
	</link>
	<link name="spine_4_rz">
		<inertial>
			<origin rpy="0.00000 0.0000 0.00000" xyz="0.00000 0.00000 0.00000"/>
			<mass value="0.00000"/>
			<inertia ixx="0.00000" ixy="0" ixz="0" iyy="0.00000" iyz="0" izz="0.00000"/>
		</inertial>
		<visual>
			<origin rpy="0.00000 0.0000 0.00000" xyz="0.00000 0.00000 0.00000"/>
			<geometry>
				<sphere radius="0.00000"/>
			</geometry>
			<material name="mat_47_0">
				<color rgba="0.71879 0.53909 0.35939 1.00000" />
			</material>
		</visual>
		<collision>
			<origin rpy="0.00000 0.0000 0.00000" xyz="0.00000 0.00000 0.00000"/>
			<geometry>
				<sphere radius="0.00000"/>
			</geometry>
		</collision>
	</link>
	<link name="spine_4_limb">
		<inertial>
			<origin rpy="0.00000 0.0000 0.00000" xyz="0.00000 0.00000 0.00000"/>
			<mass value="2.00000"/>
			<inertia ixx="0.02460" ixy="0" ixz="0" iyy="0.04485" iyz="0" izz="0.04578"/>
		</inertial>
		<visual>
			<origin rpy="0.00000 0.0000 0.00000" xyz="0.00000 0.00000 0.00000"/>
			<geometry>
				<mesh filename="/meshes/Spine3.obj" scale="1.00000 1.00000 1.00000"/>
			</geometry>
			<material name="mat_48_0">
				<color rgba="0.71879 0.53909 0.35939 1.00000" />
			</material>
		</visual>
		<collision>
			<origin rpy="0.00000 0.0000 0.00000" xyz="0.00000 0.00000 0.00000"/>
			<geometry>
				<mesh filename="/meshes/Spine3.obj" scale="1.00000 1.00000 1.00000"/>
			</geometry>
		</collision>
	</link>
	<link name="neck_rx">
		<inertial>
			<origin rpy="0.00000 0.0000 0.00000" xyz="0.00000 0.00000 0.00000"/>
			<mass value="0.00000"/>
			<inertia ixx="0.00000" ixy="0" ixz="0" iyy="0.00000" iyz="0" izz="0.00000"/>
		</inertial>
		<visual>
			<origin rpy="0.00000 0.0000 0.00000" xyz="0.00000 0.00000 0.00000"/>
			<geometry>
				<sphere radius="0.00000"/>
			</geometry>
			<material name="mat_49_0">
				<color rgba="0.71879 0.53909 0.35939 1.00000" />
			</material>
		</visual>
		<collision>
			<origin rpy="0.00000 0.0000 0.00000" xyz="0.00000 0.00000 0.00000"/>
			<geometry>
				<sphere radius="0.00000"/>
			</geometry>
		</collision>
	</link>
	<link name="neck_ry">
		<inertial>
			<origin rpy="0.00000 0.0000 0.00000" xyz="0.00000 0.00000 0.00000"/>
			<mass value="0.00000"/>
			<inertia ixx="0.00000" ixy="0" ixz="0" iyy="0.00000" iyz="0" izz="0.00000"/>
		</inertial>
		<visual>
			<origin rpy="0.00000 0.0000 0.00000" xyz="0.00000 0.00000 0.00000"/>
			<geometry>
				<sphere radius="0.00000"/>
			</geometry>
			<material name="mat_50_0">
				<color rgba="0.71879 0.53909 0.35939 1.00000" />
			</material>
		</visual>
		<collision>
			<origin rpy="0.00000 0.0000 0.00000" xyz="0.00000 0.00000 0.00000"/>
			<geometry>
				<sphere radius="0.00000"/>
			</geometry>
		</collision>
	</link>
	<link name="neck_rz">
		<inertial>
			<origin rpy="0.00000 0.0000 0.00000" xyz="0.00000 0.00000 0.00000"/>
			<mass value="0.00000"/>
			<inertia ixx="0.00000" ixy="0" ixz="0" iyy="0.00000" iyz="0" izz="0.00000"/>
		</inertial>
		<visual>
			<origin rpy="0.00000 0.0000 0.00000" xyz="0.00000 0.00000 0.00000"/>
			<geometry>
				<sphere radius="0.00000"/>
			</geometry>
			<material name="mat_51_0">
				<color rgba="0.71879 0.53909 0.35939 1.00000" />
			</material>
		</visual>
		<collision>
			<origin rpy="0.00000 0.0000 0.00000" xyz="0.00000 0.00000 0.00000"/>
			<geometry>
				<sphere radius="0.00000"/>
			</geometry>
		</collision>
	</link>
	<link name="neck_limb">
		<inertial>
			<origin rpy="0.00000 0.0000 0.00000" xyz="0.00000 0.00000 0.00000"/>
			<mass value="2.00000"/>
			<inertia ixx="0.00260" ixy="0" ixz="0" iyy="0.00362" iyz="0" izz="0.00230"/>
		</inertial>
		<visual>
			<origin rpy="0.00000 0.0000 0.00000" xyz="0.00000 0.00000 0.00000"/>
			<geometry>
				<mesh filename="/meshes/Neck.obj" scale="1.00000 1.00000 1.00000"/>
			</geometry>
			<material name="mat_52_0">
				<color rgba="0.71879 0.53909 0.35939 1.00000" />
			</material>
		</visual>
		<collision>
			<origin rpy="0.00000 0.0000 0.00000" xyz="0.00000 0.00000 0.00000"/>
			<geometry>
				<mesh filename="/meshes/Neck.obj" scale="1.00000 1.00000 1.00000"/>
			</geometry>
		</collision>
	</link>
	<link name="head_rx">
		<inertial>
			<origin rpy="0.00000 0.0000 0.00000" xyz="0.00000 0.00000 0.00000"/>
			<mass value="0.00000"/>
			<inertia ixx="0.00000" ixy="0" ixz="0" iyy="0.00000" iyz="0" izz="0.00000"/>
		</inertial>
		<visual>
			<origin rpy="0.00000 0.0000 0.00000" xyz="0.00000 0.00000 0.00000"/>
			<geometry>
				<sphere radius="0.00000"/>
			</geometry>
			<material name="mat_53_0">
				<color rgba="0.71879 0.53909 0.35939 1.00000" />
			</material>
		</visual>
		<collision>
			<origin rpy="0.00000 0.0000 0.00000" xyz="0.00000 0.00000 0.00000"/>
			<geometry>
				<sphere radius="0.00000"/>
			</geometry>
		</collision>
	</link>
	<link name="head_ry">
		<inertial>
			<origin rpy="0.00000 0.0000 0.00000" xyz="0.00000 0.00000 0.00000"/>
			<mass value="0.00000"/>
			<inertia ixx="0.00000" ixy="0" ixz="0" iyy="0.00000" iyz="0" izz="0.00000"/>
		</inertial>
		<visual>
			<origin rpy="0.00000 0.0000 0.00000" xyz="0.00000 0.00000 0.00000"/>
			<geometry>
				<sphere radius="0.00000"/>
			</geometry>
			<material name="mat_54_0">
				<color rgba="0.71879 0.53909 0.35939 1.00000" />
			</material>
		</visual>
		<collision>
			<origin rpy="0.00000 0.0000 0.00000" xyz="0.00000 0.00000 0.00000"/>
			<geometry>
				<sphere radius="0.00000"/>
			</geometry>
		</collision>
	</link>
	<link name="head_rz">
		<inertial>
			<origin rpy="0.00000 0.0000 0.00000" xyz="0.00000 0.00000 0.00000"/>
			<mass value="0.00000"/>
			<inertia ixx="0.00000" ixy="0" ixz="0" iyy="0.00000" iyz="0" izz="0.00000"/>
		</inertial>
		<visual>
			<origin rpy="0.00000 0.0000 0.00000" xyz="0.00000 0.00000 0.00000"/>
			<geometry>
				<sphere radius="0.00000"/>
			</geometry>
			<material name="mat_55_0">
				<color rgba="0.71879 0.53909 0.35939 1.00000" />
			</material>
		</visual>
		<collision>
			<origin rpy="0.00000 0.0000 0.00000" xyz="0.00000 0.00000 0.00000"/>
			<geometry>
				<sphere radius="0.00000"/>
			</geometry>
		</collision>
	</link>
	<link name="head_limb">
		<inertial>
			<origin rpy="0.00000 0.0000 0.00000" xyz="0.00000 0.00000 0.00000"/>
			<mass value="2.00000"/>
			<inertia ixx="0.00985" ixy="0" ixz="0" iyy="0.00811" iyz="0" izz="0.00814"/>
		</inertial>
		<visual>
			<origin rpy="0.00000 0.0000 0.00000" xyz="0.00000 0.00000 0.00000"/>
			<geometry>
				<mesh filename="/meshes/Head.obj" scale="1.00000 1.00000 1.00000"/>
			</geometry>
			<material name="mat_56_0">
				<color rgba="0.71879 0.53909 0.35939 1.00000" />
			</material>
		</visual>
		<collision>
			<origin rpy="0.00000 0.0000 0.00000" xyz="0.00000 0.00000 0.00000"/>
			<geometry>
				<mesh filename="/meshes/Head.obj" scale="1.00000 1.00000 1.00000"/>
			</geometry>
		</collision>
	</link>
	<link name="left_clavicle_rx">
		<inertial>
			<origin rpy="0.00000 0.0000 0.00000" xyz="0.00000 0.00000 0.00000"/>
			<mass value="0.00000"/>
			<inertia ixx="0.00000" ixy="0" ixz="0" iyy="0.00000" iyz="0" izz="0.00000"/>
		</inertial>
		<visual>
			<origin rpy="0.00000 0.0000 0.00000" xyz="0.00000 0.00000 0.00000"/>
			<geometry>
				<sphere radius="0.00000"/>
			</geometry>
			<material name="mat_57_0">
				<color rgba="0.71879 0.53909 0.35939 1.00000" />
			</material>
		</visual>
		<collision>
			<origin rpy="0.00000 0.0000 0.00000" xyz="0.00000 0.00000 0.00000"/>
			<geometry>
				<sphere radius="0.00000"/>
			</geometry>
		</collision>
	</link>
	<link name="left_clavicle_ry">
		<inertial>
			<origin rpy="0.00000 0.0000 0.00000" xyz="0.00000 0.00000 0.00000"/>
			<mass value="0.00000"/>
			<inertia ixx="0.00000" ixy="0" ixz="0" iyy="0.00000" iyz="0" izz="0.00000"/>
		</inertial>
		<visual>
			<origin rpy="0.00000 0.0000 0.00000" xyz="0.00000 0.00000 0.00000"/>
			<geometry>
				<sphere radius="0.00000"/>
			</geometry>
			<material name="mat_58_0">
				<color rgba="0.71879 0.53909 0.35939 1.00000" />
			</material>
		</visual>
		<collision>
			<origin rpy="0.00000 0.0000 0.00000" xyz="0.00000 0.00000 0.00000"/>
			<geometry>
				<sphere radius="0.00000"/>
			</geometry>
		</collision>
	</link>
	<link name="left_clavicle_rz">
		<inertial>
			<origin rpy="0.00000 0.0000 0.00000" xyz="0.00000 0.00000 0.00000"/>
			<mass value="0.00000"/>
			<inertia ixx="0.00000" ixy="0" ixz="0" iyy="0.00000" iyz="0" izz="0.00000"/>
		</inertial>
		<visual>
			<origin rpy="0.00000 0.0000 0.00000" xyz="0.00000 0.00000 0.00000"/>
			<geometry>
				<sphere radius="0.00000"/>
			</geometry>
			<material name="mat_59_0">
				<color rgba="0.71879 0.53909 0.35939 1.00000" />
			</material>
		</visual>
		<collision>
			<origin rpy="0.00000 0.0000 0.00000" xyz="0.00000 0.00000 0.00000"/>
			<geometry>
				<sphere radius="0.00000"/>
			</geometry>
		</collision>
	</link>
	<link name="left_clavicle_limb">
		<inertial>
			<origin rpy="0.00000 0.0000 0.00000" xyz="0.00000 0.00000 0.00000"/>
			<mass value="2.00000"/>
			<inertia ixx="0.00000" ixy="0" ixz="0" iyy="0.00000" iyz="0" izz="0.00000"/>
		</inertial>
		<visual>
			<origin rpy="0.00000 0.0000 0.00000" xyz="0.00000 0.00000 0.00000"/>
			<geometry>
				<mesh filename="/meshes/L_Collar.obj" scale="1.00000 1.00000 1.00000"/>
			</geometry>
			<material name="mat_60_0">
				<color rgba="0.71879 0.53909 0.35939 1.00000" />
			</material>
		</visual>
		<collision>
			<origin rpy="0.00000 0.0000 0.00000" xyz="0.00000 0.00000 0.00000"/>
			<geometry>
				<mesh filename="/meshes/L_Collar.obj" scale="1.00000 1.00000 1.00000"/>
			</geometry>
		</collision>
	</link>
	<link name="left_shoulder_rx">
		<inertial>
			<origin rpy="0.00000 0.0000 0.00000" xyz="0.00000 0.00000 0.00000"/>
			<mass value="0.00000"/>
			<inertia ixx="0.00000" ixy="0" ixz="0" iyy="0.00000" iyz="0" izz="0.00000"/>
		</inertial>
		<visual>
			<origin rpy="0.00000 0.0000 0.00000" xyz="0.00000 0.00000 0.00000"/>
			<geometry>
				<sphere radius="0.00000"/>
			</geometry>
			<material name="mat_61_0">
				<color rgba="0.71879 0.53909 0.35939 1.00000" />
			</material>
		</visual>
		<collision>
			<origin rpy="0.00000 0.0000 0.00000" xyz="0.00000 0.00000 0.00000"/>
			<geometry>
				<sphere radius="0.00000"/>
			</geometry>
		</collision>
	</link>
	<link name="left_shoulder_ry">
		<inertial>
			<origin rpy="0.00000 0.0000 0.00000" xyz="0.00000 0.00000 0.00000"/>
			<mass value="0.00000"/>
			<inertia ixx="0.00000" ixy="0" ixz="0" iyy="0.00000" iyz="0" izz="0.00000"/>
		</inertial>
		<visual>
			<origin rpy="0.00000 0.0000 0.00000" xyz="0.00000 0.00000 0.00000"/>
			<geometry>
				<sphere radius="0.00000"/>
			</geometry>
			<material name="mat_62_0">
				<color rgba="0.71879 0.53909 0.35939 1.00000" />
			</material>
		</visual>
		<collision>
			<origin rpy="0.00000 0.0000 0.00000" xyz="0.00000 0.00000 0.00000"/>
			<geometry>
				<sphere radius="0.00000"/>
			</geometry>
		</collision>
	</link>
	<link name="left_shoulder_rz">
		<inertial>
			<origin rpy="0.00000 0.0000 0.00000" xyz="0.00000 0.00000 0.00000"/>
			<mass value="0.00000"/>
			<inertia ixx="0.00000" ixy="0" ixz="0" iyy="0.00000" iyz="0" izz="0.00000"/>
		</inertial>
		<visual>
			<origin rpy="0.00000 0.0000 0.00000" xyz="0.00000 0.00000 0.00000"/>
			<geometry>
				<sphere radius="0.00000"/>
			</geometry>
			<material name="mat_63_0">
				<color rgba="0.71879 0.53909 0.35939 1.00000" />
			</material>
		</visual>
		<collision>
			<origin rpy="0.00000 0.0000 0.00000" xyz="0.00000 0.00000 0.00000"/>
			<geometry>
				<sphere radius="0.00000"/>
			</geometry>
		</collision>
	</link>
	<link name="left_shoulder_limb">
		<inertial>
			<origin rpy="0.00000 0.0000 0.00000" xyz="0.00000 0.00000 0.00000"/>
			<mass value="2.00000"/>
			<inertia ixx="0.00327" ixy="0" ixz="0" iyy="0.00641" iyz="0" izz="0.00683"/>
		</inertial>
		<visual>
			<origin rpy="0.00000 0.0000 0.00000" xyz="0.00000 0.00000 0.00000"/>
			<geometry>
				<mesh filename="/meshes/L_Shoulder.obj" scale="1.00000 1.00000 1.00000"/>
			</geometry>
			<material name="mat_64_0">
				<color rgba="0.71879 0.53909 0.35939 1.00000" />
			</material>
		</visual>
		<collision>
			<origin rpy="0.00000 0.0000 0.00000" xyz="0.00000 0.00000 0.00000"/>
			<geometry>
				<mesh filename="/meshes/L_Shoulder.obj" scale="1.00000 1.00000 1.00000"/>
			</geometry>
		</collision>
	</link>
	<link name="left_elbow_rx">
		<inertial>
			<origin rpy="0.00000 0.0000 0.00000" xyz="0.00000 0.00000 0.00000"/>
			<mass value="0.00000"/>
			<inertia ixx="0.00000" ixy="0" ixz="0" iyy="0.00000" iyz="0" izz="0.00000"/>
		</inertial>
		<visual>
			<origin rpy="0.00000 0.0000 0.00000" xyz="0.00000 0.00000 0.00000"/>
			<geometry>
				<sphere radius="0.00000"/>
			</geometry>
			<material name="mat_65_0">
				<color rgba="0.71879 0.53909 0.35939 1.00000" />
			</material>
		</visual>
		<collision>
			<origin rpy="0.00000 0.0000 0.00000" xyz="0.00000 0.00000 0.00000"/>
			<geometry>
				<sphere radius="0.00000"/>
			</geometry>
		</collision>
	</link>
	<link name="left_elbow_ry">
		<inertial>
			<origin rpy="0.00000 0.0000 0.00000" xyz="0.00000 0.00000 0.00000"/>
			<mass value="0.00000"/>
			<inertia ixx="0.00000" ixy="0" ixz="0" iyy="0.00000" iyz="0" izz="0.00000"/>
		</inertial>
		<visual>
			<origin rpy="0.00000 0.0000 0.00000" xyz="0.00000 0.00000 0.00000"/>
			<geometry>
				<sphere radius="0.00000"/>
			</geometry>
			<material name="mat_66_0">
				<color rgba="0.71879 0.53909 0.35939 1.00000" />
			</material>
		</visual>
		<collision>
			<origin rpy="0.00000 0.0000 0.00000" xyz="0.00000 0.00000 0.00000"/>
			<geometry>
				<sphere radius="0.00000"/>
			</geometry>
		</collision>
	</link>
	<link name="left_elbow_rz">
		<inertial>
			<origin rpy="0.00000 0.0000 0.00000" xyz="0.00000 0.00000 0.00000"/>
			<mass value="0.00000"/>
			<inertia ixx="0.00000" ixy="0" ixz="0" iyy="0.00000" iyz="0" izz="0.00000"/>
		</inertial>
		<visual>
			<origin rpy="0.00000 0.0000 0.00000" xyz="0.00000 0.00000 0.00000"/>
			<geometry>
				<sphere radius="0.00000"/>
			</geometry>
			<material name="mat_67_0">
				<color rgba="0.71879 0.53909 0.35939 1.00000" />
			</material>
		</visual>
		<collision>
			<origin rpy="0.00000 0.0000 0.00000" xyz="0.00000 0.00000 0.00000"/>
			<geometry>
				<sphere radius="0.00000"/>
			</geometry>
		</collision>
	</link>
	<link name="left_elbow_limb">
		<inertial>
			<origin rpy="0.00000 0.0000 0.00000" xyz="0.00000 0.00000 0.00000"/>
			<mass value="2.00000"/>
			<inertia ixx="0.00164" ixy="0" ixz="0" iyy="0.00733" iyz="0" izz="0.00755"/>
		</inertial>
		<visual>
			<origin rpy="0.00000 0.0000 0.00000" xyz="0.00000 0.00000 0.00000"/>
			<geometry>
				<mesh filename="/meshes/L_Elbow.obj" scale="1.00000 1.00000 1.00000"/>
			</geometry>
			<material name="mat_68_0">
				<color rgba="0.71879 0.53909 0.35939 1.00000" />
			</material>
		</visual>
		<collision>
			<origin rpy="0.00000 0.0000 0.00000" xyz="0.00000 0.00000 0.00000"/>
			<geometry>
				<mesh filename="/meshes/L_Elbow.obj" scale="1.00000 1.00000 1.00000"/>
			</geometry>
		</collision>
	</link>
	<link name="left_lowarm_rx">
		<inertial>
			<origin rpy="0.00000 0.0000 0.00000" xyz="0.00000 0.00000 0.00000"/>
			<mass value="0.00000"/>
			<inertia ixx="0.00000" ixy="0" ixz="0" iyy="0.00000" iyz="0" izz="0.00000"/>
		</inertial>
		<visual>
			<origin rpy="0.00000 0.0000 0.00000" xyz="0.00000 0.00000 0.00000"/>
			<geometry>
				<sphere radius="0.00000"/>
			</geometry>
			<material name="mat_69_0">
				<color rgba="0.71879 0.53909 0.35939 1.00000" />
			</material>
		</visual>
		<collision>
			<origin rpy="0.00000 0.0000 0.00000" xyz="0.00000 0.00000 0.00000"/>
			<geometry>
				<sphere radius="0.00000"/>
			</geometry>
		</collision>
	</link>
	<link name="left_lowarm_ry">
		<inertial>
			<origin rpy="0.00000 0.0000 0.00000" xyz="0.00000 0.00000 0.00000"/>
			<mass value="0.00000"/>
			<inertia ixx="0.00000" ixy="0" ixz="0" iyy="0.00000" iyz="0" izz="0.00000"/>
		</inertial>
		<visual>
			<origin rpy="0.00000 0.0000 0.00000" xyz="0.00000 0.00000 0.00000"/>
			<geometry>
				<sphere radius="0.00000"/>
			</geometry>
			<material name="mat_70_0">
				<color rgba="0.71879 0.53909 0.35939 1.00000" />
			</material>
		</visual>
		<collision>
			<origin rpy="0.00000 0.0000 0.00000" xyz="0.00000 0.00000 0.00000"/>
			<geometry>
				<sphere radius="0.00000"/>
			</geometry>
		</collision>
	</link>
	<link name="left_lowarm_rz">
		<inertial>
			<origin rpy="0.00000 0.0000 0.00000" xyz="0.00000 0.00000 0.00000"/>
			<mass value="0.00000"/>
			<inertia ixx="0.00000" ixy="0" ixz="0" iyy="0.00000" iyz="0" izz="0.00000"/>
		</inertial>
		<visual>
			<origin rpy="0.00000 0.0000 0.00000" xyz="0.00000 0.00000 0.00000"/>
			<geometry>
				<sphere radius="0.00000"/>
			</geometry>
			<material name="mat_71_0">
				<color rgba="0.71879 0.53909 0.35939 1.00000" />
			</material>
		</visual>
		<collision>
			<origin rpy="0.00000 0.0000 0.00000" xyz="0.00000 0.00000 0.00000"/>
			<geometry>
				<sphere radius="0.00000"/>
			</geometry>
		</collision>
	</link>
	<link name="left_lowarm_limb">
		<inertial>
			<origin rpy="0.00000 0.0000 0.00000" xyz="0.00000 0.00000 0.00000"/>
			<mass value="2.00000"/>
			<inertia ixx="0.00227" ixy="0" ixz="0" iyy="0.00299" iyz="0" izz="0.00143"/>
		</inertial>
		<visual>
			<origin rpy="0.00000 0.0000 0.00000" xyz="0.00000 0.00000 0.00000"/>
			<geometry>
				<mesh filename="/meshes/L_Wrist.obj" scale="1.00000 1.00000 1.00000"/>
			</geometry>
			<material name="mat_72_0">
				<color rgba="0.71879 0.53909 0.35939 1.00000" />
			</material>
		</visual>
		<collision>
			<origin rpy="0.00000 0.0000 0.00000" xyz="0.00000 0.00000 0.00000"/>
			<geometry>
				<mesh filename="/meshes/L_Wrist.obj" scale="1.00000 1.00000 1.00000"/>
			</geometry>
		</collision>
	</link>
	<link name="left_hand_rx">
		<inertial>
			<origin rpy="0.00000 0.0000 0.00000" xyz="0.00000 0.00000 0.00000"/>
			<mass value="0.00000"/>
			<inertia ixx="0.00000" ixy="0" ixz="0" iyy="0.00000" iyz="0" izz="0.00000"/>
		</inertial>
		<visual>
			<origin rpy="0.00000 0.0000 0.00000" xyz="0.00000 0.00000 0.00000"/>
			<geometry>
				<sphere radius="0.00000"/>
			</geometry>
			<material name="mat_73_0">
				<color rgba="0.71879 0.53909 0.35939 1.00000" />
			</material>
		</visual>
		<collision>
			<origin rpy="0.00000 0.0000 0.00000" xyz="0.00000 0.00000 0.00000"/>
			<geometry>
				<sphere radius="0.00000"/>
			</geometry>
		</collision>
	</link>
	<link name="left_hand_ry">
		<inertial>
			<origin rpy="0.00000 0.0000 0.00000" xyz="0.00000 0.00000 0.00000"/>
			<mass value="0.00000"/>
			<inertia ixx="0.00000" ixy="0" ixz="0" iyy="0.00000" iyz="0" izz="0.00000"/>
		</inertial>
		<visual>
			<origin rpy="0.00000 0.0000 0.00000" xyz="0.00000 0.00000 0.00000"/>
			<geometry>
				<sphere radius="0.00000"/>
			</geometry>
			<material name="mat_74_0">
				<color rgba="0.71879 0.53909 0.35939 1.00000" />
			</material>
		</visual>
		<collision>
			<origin rpy="0.00000 0.0000 0.00000" xyz="0.00000 0.00000 0.00000"/>
			<geometry>
				<sphere radius="0.00000"/>
			</geometry>
		</collision>
	</link>
	<link name="left_hand_rz">
		<inertial>
			<origin rpy="0.00000 0.0000 0.00000" xyz="0.00000 0.00000 0.00000"/>
			<mass value="0.00000"/>
			<inertia ixx="0.00000" ixy="0" ixz="0" iyy="0.00000" iyz="0" izz="0.00000"/>
		</inertial>
		<visual>
			<origin rpy="0.00000 0.0000 0.00000" xyz="0.00000 0.00000 0.00000"/>
			<geometry>
				<sphere radius="0.00000"/>
			</geometry>
			<material name="mat_75_0">
				<color rgba="0.71879 0.53909 0.35939 1.00000" />
			</material>
		</visual>
		<collision>
			<origin rpy="0.00000 0.0000 0.00000" xyz="0.00000 0.00000 0.00000"/>
			<geometry>
				<sphere radius="0.00000"/>
			</geometry>
		</collision>
	</link>
	<link name="left_hand_limb">
		<inertial>
			<origin rpy="0.00000 0.0000 0.00000" xyz="0.00000 0.00000 0.00000"/>
			<mass value="2.00000"/>
			<inertia ixx="0.00066" ixy="0" ixz="0" iyy="0.00128" iyz="0" izz="0.00075"/>
		</inertial>
		<visual>
			<origin rpy="0.00000 0.0000 0.00000" xyz="0.00000 0.00000 0.00000"/>
			<geometry>
				<mesh filename="/meshes/L_Hand.obj" scale="1.00000 1.00000 1.00000"/>
			</geometry>
			<material name="mat_76_0">
				<color rgba="0.71879 0.53909 0.35939 1.00000" />
			</material>
		</visual>
		<collision>
			<origin rpy="0.00000 0.0000 0.00000" xyz="0.00000 0.00000 0.00000"/>
			<geometry>
				<mesh filename="/meshes/L_Hand.obj" scale="1.00000 1.00000 1.00000"/>
			</geometry>
		</collision>
	</link>
	<link name="right_clavicle_rx">
		<inertial>
			<origin rpy="0.00000 0.0000 0.00000" xyz="0.00000 0.00000 0.00000"/>
			<mass value="0.00000"/>
			<inertia ixx="0.00000" ixy="0" ixz="0" iyy="0.00000" iyz="0" izz="0.00000"/>
		</inertial>
		<visual>
			<origin rpy="0.00000 0.0000 0.00000" xyz="0.00000 0.00000 0.00000"/>
			<geometry>
				<sphere radius="0.00000"/>
			</geometry>
			<material name="mat_77_0">
				<color rgba="0.71879 0.53909 0.35939 1.00000" />
			</material>
		</visual>
		<collision>
			<origin rpy="0.00000 0.0000 0.00000" xyz="0.00000 0.00000 0.00000"/>
			<geometry>
				<sphere radius="0.00000"/>
			</geometry>
		</collision>
	</link>
	<link name="right_clavicle_ry">
		<inertial>
			<origin rpy="0.00000 0.0000 0.00000" xyz="0.00000 0.00000 0.00000"/>
			<mass value="0.00000"/>
			<inertia ixx="0.00000" ixy="0" ixz="0" iyy="0.00000" iyz="0" izz="0.00000"/>
		</inertial>
		<visual>
			<origin rpy="0.00000 0.0000 0.00000" xyz="0.00000 0.00000 0.00000"/>
			<geometry>
				<sphere radius="0.00000"/>
			</geometry>
			<material name="mat_78_0">
				<color rgba="0.71879 0.53909 0.35939 1.00000" />
			</material>
		</visual>
		<collision>
			<origin rpy="0.00000 0.0000 0.00000" xyz="0.00000 0.00000 0.00000"/>
			<geometry>
				<sphere radius="0.00000"/>
			</geometry>
		</collision>
	</link>
	<link name="right_clavicle_rz">
		<inertial>
			<origin rpy="0.00000 0.0000 0.00000" xyz="0.00000 0.00000 0.00000"/>
			<mass value="0.00000"/>
			<inertia ixx="0.00000" ixy="0" ixz="0" iyy="0.00000" iyz="0" izz="0.00000"/>
		</inertial>
		<visual>
			<origin rpy="0.00000 0.0000 0.00000" xyz="0.00000 0.00000 0.00000"/>
			<geometry>
				<sphere radius="0.00000"/>
			</geometry>
			<material name="mat_79_0">
				<color rgba="0.71879 0.53909 0.35939 1.00000" />
			</material>
		</visual>
		<collision>
			<origin rpy="0.00000 0.0000 0.00000" xyz="0.00000 0.00000 0.00000"/>
			<geometry>
				<sphere radius="0.00000"/>
			</geometry>
		</collision>
	</link>
	<link name="right_clavicle_limb">
		<inertial>
			<origin rpy="0.00000 0.0000 0.00000" xyz="0.00000 0.00000 0.00000"/>
			<mass value="2.00000"/>
			<inertia ixx="0.00000" ixy="0" ixz="0" iyy="0.00000" iyz="0" izz="0.00000"/>
		</inertial>
		<visual>
			<origin rpy="0.00000 0.0000 0.00000" xyz="0.00000 0.00000 0.00000"/>
			<geometry>
				<mesh filename="/meshes/R_Collar.obj" scale="1.00000 1.00000 1.00000"/>
			</geometry>
			<material name="mat_80_0">
				<color rgba="0.71879 0.53909 0.35939 1.00000" />
			</material>
		</visual>
		<collision>
			<origin rpy="0.00000 0.0000 0.00000" xyz="0.00000 0.00000 0.00000"/>
			<geometry>
				<mesh filename="/meshes/R_Collar.obj" scale="1.00000 1.00000 1.00000"/>
			</geometry>
		</collision>
	</link>
	<link name="right_shoulder_rx">
		<inertial>
			<origin rpy="0.00000 0.0000 0.00000" xyz="0.00000 0.00000 0.00000"/>
			<mass value="0.00000"/>
			<inertia ixx="0.00000" ixy="0" ixz="0" iyy="0.00000" iyz="0" izz="0.00000"/>
		</inertial>
		<visual>
			<origin rpy="0.00000 0.0000 0.00000" xyz="0.00000 0.00000 0.00000"/>
			<geometry>
				<sphere radius="0.00000"/>
			</geometry>
			<material name="mat_81_0">
				<color rgba="0.71879 0.53909 0.35939 1.00000" />
			</material>
		</visual>
		<collision>
			<origin rpy="0.00000 0.0000 0.00000" xyz="0.00000 0.00000 0.00000"/>
			<geometry>
				<sphere radius="0.00000"/>
			</geometry>
		</collision>
	</link>
	<link name="right_shoulder_ry">
		<inertial>
			<origin rpy="0.00000 0.0000 0.00000" xyz="0.00000 0.00000 0.00000"/>
			<mass value="0.00000"/>
			<inertia ixx="0.00000" ixy="0" ixz="0" iyy="0.00000" iyz="0" izz="0.00000"/>
		</inertial>
		<visual>
			<origin rpy="0.00000 0.0000 0.00000" xyz="0.00000 0.00000 0.00000"/>
			<geometry>
				<sphere radius="0.00000"/>
			</geometry>
			<material name="mat_82_0">
				<color rgba="0.71879 0.53909 0.35939 1.00000" />
			</material>
		</visual>
		<collision>
			<origin rpy="0.00000 0.0000 0.00000" xyz="0.00000 0.00000 0.00000"/>
			<geometry>
				<sphere radius="0.00000"/>
			</geometry>
		</collision>
	</link>
	<link name="right_shoulder_rz">
		<inertial>
			<origin rpy="0.00000 0.0000 0.00000" xyz="0.00000 0.00000 0.00000"/>
			<mass value="0.00000"/>
			<inertia ixx="0.00000" ixy="0" ixz="0" iyy="0.00000" iyz="0" izz="0.00000"/>
		</inertial>
		<visual>
			<origin rpy="0.00000 0.0000 0.00000" xyz="0.00000 0.00000 0.00000"/>
			<geometry>
				<sphere radius="0.00000"/>
			</geometry>
			<material name="mat_83_0">
				<color rgba="0.71879 0.53909 0.35939 1.00000" />
			</material>
		</visual>
		<collision>
			<origin rpy="0.00000 0.0000 0.00000" xyz="0.00000 0.00000 0.00000"/>
			<geometry>
				<sphere radius="0.00000"/>
			</geometry>
		</collision>
	</link>
	<link name="right_shoulder_limb">
		<inertial>
			<origin rpy="0.00000 0.0000 0.00000" xyz="0.00000 0.00000 0.00000"/>
			<mass value="2.00000"/>
			<inertia ixx="0.00355" ixy="0" ixz="0" iyy="0.00652" iyz="0" izz="0.00686"/>
		</inertial>
		<visual>
			<origin rpy="0.00000 0.0000 0.00000" xyz="0.00000 0.00000 0.00000"/>
			<geometry>
				<mesh filename="/meshes/R_Shoulder.obj" scale="1.00000 1.00000 1.00000"/>
			</geometry>
			<material name="mat_84_0">
				<color rgba="0.71879 0.53909 0.35939 1.00000" />
			</material>
		</visual>
		<collision>
			<origin rpy="0.00000 0.0000 0.00000" xyz="0.00000 0.00000 0.00000"/>
			<geometry>
				<mesh filename="/meshes/R_Shoulder.obj" scale="1.00000 1.00000 1.00000"/>
			</geometry>
		</collision>
	</link>
	<link name="right_elbow_rx">
		<inertial>
			<origin rpy="0.00000 0.0000 0.00000" xyz="0.00000 0.00000 0.00000"/>
			<mass value="0.00000"/>
			<inertia ixx="0.00000" ixy="0" ixz="0" iyy="0.00000" iyz="0" izz="0.00000"/>
		</inertial>
		<visual>
			<origin rpy="0.00000 0.0000 0.00000" xyz="0.00000 0.00000 0.00000"/>
			<geometry>
				<sphere radius="0.00000"/>
			</geometry>
			<material name="mat_85_0">
				<color rgba="0.71879 0.53909 0.35939 1.00000" />
			</material>
		</visual>
		<collision>
			<origin rpy="0.00000 0.0000 0.00000" xyz="0.00000 0.00000 0.00000"/>
			<geometry>
				<sphere radius="0.00000"/>
			</geometry>
		</collision>
	</link>
	<link name="right_elbow_ry">
		<inertial>
			<origin rpy="0.00000 0.0000 0.00000" xyz="0.00000 0.00000 0.00000"/>
			<mass value="0.00000"/>
			<inertia ixx="0.00000" ixy="0" ixz="0" iyy="0.00000" iyz="0" izz="0.00000"/>
		</inertial>
		<visual>
			<origin rpy="0.00000 0.0000 0.00000" xyz="0.00000 0.00000 0.00000"/>
			<geometry>
				<sphere radius="0.00000"/>
			</geometry>
			<material name="mat_86_0">
				<color rgba="0.71879 0.53909 0.35939 1.00000" />
			</material>
		</visual>
		<collision>
			<origin rpy="0.00000 0.0000 0.00000" xyz="0.00000 0.00000 0.00000"/>
			<geometry>
				<sphere radius="0.00000"/>
			</geometry>
		</collision>
	</link>
	<link name="right_elbow_rz">
		<inertial>
			<origin rpy="0.00000 0.0000 0.00000" xyz="0.00000 0.00000 0.00000"/>
			<mass value="0.00000"/>
			<inertia ixx="0.00000" ixy="0" ixz="0" iyy="0.00000" iyz="0" izz="0.00000"/>
		</inertial>
		<visual>
			<origin rpy="0.00000 0.0000 0.00000" xyz="0.00000 0.00000 0.00000"/>
			<geometry>
				<sphere radius="0.00000"/>
			</geometry>
			<material name="mat_87_0">
				<color rgba="0.71879 0.53909 0.35939 1.00000" />
			</material>
		</visual>
		<collision>
			<origin rpy="0.00000 0.0000 0.00000" xyz="0.00000 0.00000 0.00000"/>
			<geometry>
				<sphere radius="0.00000"/>
			</geometry>
		</collision>
	</link>
	<link name="right_elbow_limb">
		<inertial>
			<origin rpy="0.00000 0.0000 0.00000" xyz="0.00000 0.00000 0.00000"/>
			<mass value="2.00000"/>
			<inertia ixx="0.00170" ixy="0" ixz="0" iyy="0.00717" iyz="0" izz="0.00735"/>
		</inertial>
		<visual>
			<origin rpy="0.00000 0.0000 0.00000" xyz="0.00000 0.00000 0.00000"/>
			<geometry>
				<mesh filename="/meshes/R_Elbow.obj" scale="1.00000 1.00000 1.00000"/>
			</geometry>
			<material name="mat_88_0">
				<color rgba="0.71879 0.53909 0.35939 1.00000" />
			</material>
		</visual>
		<collision>
			<origin rpy="0.00000 0.0000 0.00000" xyz="0.00000 0.00000 0.00000"/>
			<geometry>
				<mesh filename="/meshes/R_Elbow.obj" scale="1.00000 1.00000 1.00000"/>
			</geometry>
		</collision>
	</link>
	<link name="right_lowarm_rx">
		<inertial>
			<origin rpy="0.00000 0.0000 0.00000" xyz="0.00000 0.00000 0.00000"/>
			<mass value="0.00000"/>
			<inertia ixx="0.00000" ixy="0" ixz="0" iyy="0.00000" iyz="0" izz="0.00000"/>
		</inertial>
		<visual>
			<origin rpy="0.00000 0.0000 0.00000" xyz="0.00000 0.00000 0.00000"/>
			<geometry>
				<sphere radius="0.00000"/>
			</geometry>
			<material name="mat_89_0">
				<color rgba="0.71879 0.53909 0.35939 1.00000" />
			</material>
		</visual>
		<collision>
			<origin rpy="0.00000 0.0000 0.00000" xyz="0.00000 0.00000 0.00000"/>
			<geometry>
				<sphere radius="0.00000"/>
			</geometry>
		</collision>
	</link>
	<link name="right_lowarm_ry">
		<inertial>
			<origin rpy="0.00000 0.0000 0.00000" xyz="0.00000 0.00000 0.00000"/>
			<mass value="0.00000"/>
			<inertia ixx="0.00000" ixy="0" ixz="0" iyy="0.00000" iyz="0" izz="0.00000"/>
		</inertial>
		<visual>
			<origin rpy="0.00000 0.0000 0.00000" xyz="0.00000 0.00000 0.00000"/>
			<geometry>
				<sphere radius="0.00000"/>
			</geometry>
			<material name="mat_90_0">
				<color rgba="0.71879 0.53909 0.35939 1.00000" />
			</material>
		</visual>
		<collision>
			<origin rpy="0.00000 0.0000 0.00000" xyz="0.00000 0.00000 0.00000"/>
			<geometry>
				<sphere radius="0.00000"/>
			</geometry>
		</collision>
	</link>
	<link name="right_lowarm_rz">
		<inertial>
			<origin rpy="0.00000 0.0000 0.00000" xyz="0.00000 0.00000 0.00000"/>
			<mass value="0.00000"/>
			<inertia ixx="0.00000" ixy="0" ixz="0" iyy="0.00000" iyz="0" izz="0.00000"/>
		</inertial>
		<visual>
			<origin rpy="0.00000 0.0000 0.00000" xyz="0.00000 0.00000 0.00000"/>
			<geometry>
				<sphere radius="0.00000"/>
			</geometry>
			<material name="mat_91_0">
				<color rgba="0.71879 0.53909 0.35939 1.00000" />
			</material>
		</visual>
		<collision>
			<origin rpy="0.00000 0.0000 0.00000" xyz="0.00000 0.00000 0.00000"/>
			<geometry>
				<sphere radius="0.00000"/>
			</geometry>
		</collision>
	</link>
	<link name="right_lowarm_limb">
		<inertial>
			<origin rpy="0.00000 0.0000 0.00000" xyz="0.00000 0.00000 0.00000"/>
			<mass value="2.00000"/>
			<inertia ixx="0.00236" ixy="0" ixz="0" iyy="0.00304" iyz="0" izz="0.00140"/>
		</inertial>
		<visual>
			<origin rpy="0.00000 0.0000 0.00000" xyz="0.00000 0.00000 0.00000"/>
			<geometry>
				<mesh filename="/meshes/R_Wrist.obj" scale="1.00000 1.00000 1.00000"/>
			</geometry>
			<material name="mat_92_0">
				<color rgba="0.71879 0.53909 0.35939 1.00000" />
			</material>
		</visual>
		<collision>
			<origin rpy="0.00000 0.0000 0.00000" xyz="0.00000 0.00000 0.00000"/>
			<geometry>
				<mesh filename="/meshes/R_Wrist.obj" scale="1.00000 1.00000 1.00000"/>
			</geometry>
		</collision>
	</link>
	<link name="right_hand_rx">
		<inertial>
			<origin rpy="0.00000 0.0000 0.00000" xyz="0.00000 0.00000 0.00000"/>
			<mass value="0.00000"/>
			<inertia ixx="0.00000" ixy="0" ixz="0" iyy="0.00000" iyz="0" izz="0.00000"/>
		</inertial>
		<visual>
			<origin rpy="0.00000 0.0000 0.00000" xyz="0.00000 0.00000 0.00000"/>
			<geometry>
				<sphere radius="0.00000"/>
			</geometry>
			<material name="mat_93_0">
				<color rgba="0.71879 0.53909 0.35939 1.00000" />
			</material>
		</visual>
		<collision>
			<origin rpy="0.00000 0.0000 0.00000" xyz="0.00000 0.00000 0.00000"/>
			<geometry>
				<sphere radius="0.00000"/>
			</geometry>
		</collision>
	</link>
	<link name="right_hand_ry">
		<inertial>
			<origin rpy="0.00000 0.0000 0.00000" xyz="0.00000 0.00000 0.00000"/>
			<mass value="0.00000"/>
			<inertia ixx="0.00000" ixy="0" ixz="0" iyy="0.00000" iyz="0" izz="0.00000"/>
		</inertial>
		<visual>
			<origin rpy="0.00000 0.0000 0.00000" xyz="0.00000 0.00000 0.00000"/>
			<geometry>
				<sphere radius="0.00000"/>
			</geometry>
			<material name="mat_94_0">
				<color rgba="0.71879 0.53909 0.35939 1.00000" />
			</material>
		</visual>
		<collision>
			<origin rpy="0.00000 0.0000 0.00000" xyz="0.00000 0.00000 0.00000"/>
			<geometry>
				<sphere radius="0.00000"/>
			</geometry>
		</collision>
	</link>
	<link name="right_hand_rz">
		<inertial>
			<origin rpy="0.00000 0.0000 0.00000" xyz="0.00000 0.00000 0.00000"/>
			<mass value="0.00000"/>
			<inertia ixx="0.00000" ixy="0" ixz="0" iyy="0.00000" iyz="0" izz="0.00000"/>
		</inertial>
		<visual>
			<origin rpy="0.00000 0.0000 0.00000" xyz="0.00000 0.00000 0.00000"/>
			<geometry>
				<sphere radius="0.00000"/>
			</geometry>
			<material name="mat_95_0">
				<color rgba="0.71879 0.53909 0.35939 1.00000" />
			</material>
		</visual>
		<collision>
			<origin rpy="0.00000 0.0000 0.00000" xyz="0.00000 0.00000 0.00000"/>
			<geometry>
				<sphere radius="0.00000"/>
			</geometry>
		</collision>
	</link>
	<link name="right_hand_limb">
		<inertial>
			<origin rpy="0.00000 0.0000 0.00000" xyz="0.00000 0.00000 0.00000"/>
			<mass value="2.00000"/>
			<inertia ixx="0.00068" ixy="0" ixz="0" iyy="0.00127" iyz="0" izz="0.00072"/>
		</inertial>
		<visual>
			<origin rpy="0.00000 0.0000 0.00000" xyz="0.00000 0.00000 0.00000"/>
			<geometry>
				<mesh filename="/meshes/R_Hand.obj" scale="1.00000 1.00000 1.00000"/>
			</geometry>
			<material name="mat_96_0">
				<color rgba="0.71879 0.53909 0.35939 1.00000" />
			</material>
		</visual>
		<collision>
			<origin rpy="0.00000 0.0000 0.00000" xyz="0.00000 0.00000 0.00000"/>
			<geometry>
				<mesh filename="/meshes/R_Hand.obj" scale="1.00000 1.00000 1.00000"/>
			</geometry>
		</collision>
	</link>
	<joint name="pelvis" type="fixed">
		<parent link="base"/>
		<child link="pelvis_limb"/>
		<dynamics damping="1.0" friction="0.0001"/>
		<origin rpy="0.00000 0.0000 0.00000" xyz="0.00000 0.00000 0.00000"/>
		<axis xyz="0.00000 0.00000 0.00000"/>
	</joint>
	<joint name="left_hip_rx" type="revolute">
		<parent link="pelvis_limb"/>
		<child link="left_hip_rx"/>
		<limit effort="1000.00000" lower="-3.14" upper="3.14" velocity="0.00000"/>
		<dynamics damping="1.0" friction="0.0001"/>
		<origin rpy="0.00000 0.0000 0.00000" xyz="0.05858 -0.08228 -0.01766"/>
		<axis xyz="1.00000 0.00000 0.00000"/>
	</joint>
	<joint name="left_hip_ry" type="revolute">
		<parent link="left_hip_rx"/>
		<child link="left_hip_ry"/>
		<limit effort="1000.00000" lower="-3.14" upper="3.14" velocity="0.00000"/>
		<dynamics damping="1.0" friction="0.0001"/>
		<origin rpy="0.00000 0.0000 0.00000" xyz="0.00000 0.00000 0.00000"/>
		<axis xyz="0.00000 1.00000 0.00000"/>
	</joint>
	<joint name="left_hip_rz" type="revolute">
		<parent link="left_hip_ry"/>
		<child link="left_hip_rz"/>
		<limit effort="1000.00000" lower="-3.14" upper="3.14" velocity="0.00000"/>
		<dynamics damping="1.0" friction="0.0001"/>
		<origin rpy="0.00000 0.0000 0.00000" xyz="0.00000 0.00000 0.00000"/>
		<axis xyz="0.00000 0.00000 1.00000"/>
	</joint>
	<joint name="left_hip_rzdammy" type="fixed">
		<parent link="left_hip_rz"/>
		<child link="left_hip_limb"/>
		<origin rpy="0.00000 0.0000 0.00000" xyz="0.00000 0.00000 0.00000"/>
	</joint>
	<joint name="left_knee_rx" type="revolute">
		<parent link="left_hip_limb"/>
		<child link="left_knee_rx"/>
		<limit effort="1000.00000" lower="-3.14" upper="3.14" velocity="0.00000"/>
		<dynamics damping="1.0" friction="0.0001"/>
		<origin rpy="0.00000 0.0000 0.00000" xyz="0.04345 -0.38647 0.00804"/>
		<axis xyz="1.00000 0.00000 0.00000"/>
	</joint>
	<joint name="left_knee_ry" type="revolute">
		<parent link="left_knee_rx"/>
		<child link="left_knee_ry"/>
		<limit effort="1000.00000" lower="-3.14" upper="3.14" velocity="0.00000"/>
		<dynamics damping="1.0" friction="0.0001"/>
		<origin rpy="0.00000 0.0000 0.00000" xyz="0.00000 0.00000 0.00000"/>
		<axis xyz="0.00000 1.00000 0.00000"/>
	</joint>
	<joint name="left_knee_rz" type="revolute">
		<parent link="left_knee_ry"/>
		<child link="left_knee_rz"/>
		<limit effort="1000.00000" lower="-3.14" upper="3.14" velocity="0.00000"/>
		<dynamics damping="1.0" friction="0.0001"/>
		<origin rpy="0.00000 0.0000 0.00000" xyz="0.00000 0.00000 0.00000"/>
		<axis xyz="0.00000 0.00000 1.00000"/>
	</joint>
	<joint name="left_knee_rzdammy" type="fixed">
		<parent link="left_knee_rz"/>
		<child link="left_knee_limb"/>
		<dynamics damping="1.0" friction="0.0001"/>
		<origin rpy="0.00000 0.0000 0.00000" xyz="0.00000 0.00000 0.00000"/>
		<axis xyz="0.00000 0.00000 0.00000"/>
	</joint>
	<joint name="left_ankle_rx" type="revolute">
		<parent link="left_knee_limb"/>
		<child link="left_ankle_rx"/>
		<limit effort="1000.00000" lower="-3.14" upper="3.14" velocity="0.00000"/>
		<dynamics damping="1.0" friction="0.0001"/>
		<origin rpy="0.00000 0.0000 0.00000" xyz="-0.01479 -0.42687 -0.03743"/>
		<axis xyz="1.00000 0.00000 0.00000"/>
	</joint>
	<joint name="left_ankle_ry" type="revolute">
		<parent link="left_ankle_rx"/>
		<child link="left_ankle_ry"/>
		<limit effort="1000.00000" lower="-3.14" upper="3.14" velocity="0.00000"/>
		<dynamics damping="1.0" friction="0.0001"/>
		<origin rpy="0.00000 0.0000 0.00000" xyz="0.00000 0.00000 0.00000"/>
		<axis xyz="0.00000 1.00000 0.00000"/>
	</joint>
	<joint name="left_ankle_rz" type="revolute">
		<parent link="left_ankle_ry"/>
		<child link="left_ankle_rz"/>
		<limit effort="1000.00000" lower="-3.14" upper="3.14" velocity="0.00000"/>
		<dynamics damping="1.0" friction="0.0001"/>
		<origin rpy="0.00000 0.0000 0.00000" xyz="0.00000 0.00000 0.00000"/>
		<axis xyz="0.00000 0.00000 1.00000"/>
	</joint>
	<joint name="left_ankle_rzdammy" type="fixed">
		<parent link="left_ankle_rz"/>
		<child link="left_ankle_limb"/>
		<origin rpy="0.00000 0.0000 0.00000" xyz="0.00000 0.00000 0.00000"/>
	</joint>
	<joint name="left_foot_rx" type="revolute">
		<parent link="left_ankle_limb"/>
		<child link="left_foot_rx"/>
		<limit effort="1000.00000" lower="-3.14" upper="3.14" velocity="0.00000"/>
		<dynamics damping="1.0" friction="0.0001"/>
		<origin rpy="0.00000 0.0000 0.00000" xyz="0.04105 -0.06029 0.12204"/>
		<axis xyz="1.00000 0.00000 0.00000"/>
	</joint>
	<joint name="left_foot_ry" type="revolute">
		<parent link="left_foot_rx"/>
		<child link="left_foot_ry"/>
		<limit effort="1000.00000" lower="-3.14" upper="3.14" velocity="0.00000"/>
		<dynamics damping="1.0" friction="0.0001"/>
		<origin rpy="0.00000 0.0000 0.00000" xyz="0.00000 0.00000 0.00000"/>
		<axis xyz="0.00000 1.00000 0.00000"/>
	</joint>
	<joint name="left_foot_rz" type="revolute">
		<parent link="left_foot_ry"/>
		<child link="left_foot_rz"/>
		<limit effort="0.00000" lower="-3.14" upper="3.14" velocity="0.00000"/>
		<dynamics damping="1.0" friction="0.0001"/>
		<origin rpy="0.00000 0.0000 0.00000" xyz="0.00000 0.00000 0.00000"/>
		<axis xyz="0.00000 0.00000 1.00000"/>
	</joint>
	<joint name="left_foot_rzdammy" type="fixed">
		<parent link="left_foot_rz"/>
		<child link="left_foot_limb"/>
		<origin rpy="0.00000 0.0000 0.00000" xyz="0.00000 0.00000 0.00000"/>
	</joint>
	<joint name="right_hip_rx" type="revolute">
		<parent link="pelvis_limb"/>
		<child link="right_hip_rx"/>
		<limit effort="1000.00000" lower="-3.14" upper="3.14" velocity="0.00000"/>
		<dynamics damping="1.0" friction="0.0001"/>
		<origin rpy="0.00000 0.0000 0.00000" xyz="-0.06031 -0.09051 -0.01354"/>
		<axis xyz="1.00000 0.00000 0.00000"/>
	</joint>
	<joint name="right_hip_ry" type="revolute">
		<parent link="right_hip_rx"/>
		<child link="right_hip_ry"/>
		<limit effort="1000.00000" lower="-3.14" upper="3.14" velocity="0.00000"/>
		<dynamics damping="1.0" friction="0.0001"/>
		<origin rpy="0.00000 0.0000 0.00000" xyz="0.00000 0.00000 0.00000"/>
		<axis xyz="0.00000 1.00000 0.00000"/>
	</joint>
	<joint name="right_hip_rz" type="revolute">
		<parent link="right_hip_ry"/>
		<child link="right_hip_rz"/>
		<limit effort="1000.00000" lower="-3.14" upper="3.14" velocity="0.00000"/>
		<dynamics damping="1.0" friction="0.0001"/>
		<origin rpy="0.00000 0.0000 0.00000" xyz="0.00000 0.00000 0.00000"/>
		<axis xyz="0.00000 0.00000 1.00000"/>
	</joint>
	<joint name="right_hip_rzdammy" type="fixed">
		<parent link="right_hip_rz"/>
		<child link="right_hip_limb"/>
		<origin rpy="0.00000 0.0000 0.00000" xyz="0.00000 0.00000 0.00000"/>
	</joint>
	<joint name="right_knee_rx" type="revolute">
		<parent link="right_hip_limb"/>
		<child link="right_knee_rx"/>
		<limit effort="1000.00000" lower="-3.14" upper="3.14" velocity="0.00000"/>
		<dynamics damping="1.0" friction="0.0001"/>
		<origin rpy="0.00000 0.0000 0.00000" xyz="-0.04326 -0.38369 -0.00484"/>
		<axis xyz="1.00000 0.00000 0.00000"/>
	</joint>
	<joint name="right_knee_ry" type="revolute">
		<parent link="right_knee_rx"/>
		<child link="right_knee_ry"/>
		<limit effort="1000.00000" lower="-3.14" upper="3.14" velocity="0.00000"/>
		<dynamics damping="1.0" friction="0.0001"/>
		<origin rpy="0.00000 0.0000 0.00000" xyz="0.00000 0.00000 0.00000"/>
		<axis xyz="0.00000 1.00000 0.00000"/>
	</joint>
	<joint name="right_knee_rz" type="revolute">
		<parent link="right_knee_ry"/>
		<child link="right_knee_rz"/>
		<limit effort="1000.00000" lower="-3.14" upper="3.14" velocity="0.00000"/>
		<dynamics damping="1.0" friction="0.0001"/>
		<origin rpy="0.00000 0.0000 0.00000" xyz="0.00000 0.00000 0.00000"/>
		<axis xyz="0.00000 0.00000 1.00000"/>
	</joint>
	<joint name="right_knee_rzdammy" type="fixed">
		<parent link="right_knee_rz"/>
		<child link="right_knee_limb"/>
		<origin rpy="0.00000 0.0000 0.00000" xyz="0.00000 0.00000 0.00000"/>
	</joint>
	<joint name="right_ankle_rx" type="revolute">
		<parent link="right_knee_limb"/>
		<child link="right_ankle_rx"/>
		<limit effort="1000.00000" lower="-3.14" upper="3.14" velocity="0.00000"/>
		<dynamics damping="1.0" friction="0.0001"/>
		<origin rpy="0.00000 0.0000 0.00000" xyz="0.01906 -0.42005 -0.03456"/>
		<axis xyz="1.00000 0.00000 0.00000"/>
	</joint>
	<joint name="right_ankle_ry" type="revolute">
		<parent link="right_ankle_rx"/>
		<child link="right_ankle_ry"/>
		<limit effort="1000.00000" lower="-3.14" upper="3.14" velocity="0.00000"/>
		<dynamics damping="1.0" friction="0.0001"/>
		<origin rpy="0.00000 0.0000 0.00000" xyz="0.00000 0.00000 0.00000"/>
		<axis xyz="0.00000 1.00000 0.00000"/>
	</joint>
	<joint name="right_ankle_rz" type="revolute">
		<parent link="right_ankle_ry"/>
		<child link="right_ankle_rz"/>
		<limit effort="1000.00000" lower="-3.14" upper="3.14" velocity="0.00000"/>
		<dynamics damping="1.0" friction="0.0001"/>
		<origin rpy="0.00000 0.0000 0.00000" xyz="0.00000 0.00000 0.00000"/>
		<axis xyz="0.00000 0.00000 1.00000"/>
	</joint>
	<joint name="right_ankle_rzdammy" type="fixed">
		<parent link="right_ankle_rz"/>
		<child link="right_ankle_limb"/>
		<origin rpy="0.00000 0.0000 0.00000" xyz="0.00000 0.00000 0.00000"/>
	</joint>
	<joint name="right_foot_rx" type="revolute">
		<parent link="right_ankle_limb"/>
		<child link="right_foot_rx"/>
		<limit effort="1000.00000" lower="-3.14" upper="3.14" velocity="0.00000"/>
		<dynamics damping="1.0" friction="0.0001"/>
		<origin rpy="0.00000 0.0000 0.00000" xyz="-0.03484 -0.06211 0.13032"/>
		<axis xyz="1.00000 0.00000 0.00000"/>
	</joint>
	<joint name="right_foot_ry" type="revolute">
		<parent link="right_foot_rx"/>
		<child link="right_foot_ry"/>
		<limit effort="1000.00000" lower="-3.14" upper="3.14" velocity="0.00000"/>
		<dynamics damping="1.0" friction="0.0001"/>
		<origin rpy="0.00000 0.0000 0.00000" xyz="0.00000 0.00000 0.00000"/>
		<axis xyz="0.00000 1.00000 0.00000"/>
	</joint>
	<joint name="right_foot_rz" type="revolute">
		<parent link="right_foot_ry"/>
		<child link="right_foot_rz"/>
		<limit effort="1000.00000" lower="-3.14" upper="3.14" velocity="0.00000"/>
		<dynamics damping="1.0" friction="0.0001"/>
		<origin rpy="0.00000 0.0000 0.00000" xyz="0.00000 0.00000 0.00000"/>
		<axis xyz="0.00000 0.00000 1.00000"/>
	</joint>
	<joint name="right_foot_rzdammy" type="fixed">
		<parent link="right_foot_rz"/>
		<child link="right_foot_limb"/>
		<origin rpy="0.00000 0.0000 0.00000" xyz="0.00000 0.00000 0.00000"/>
	</joint>
	<joint name="spine_2_rx" type="revolute">
		<parent link="pelvis_limb"/>
		<child link="spine_2_rx"/>
		<limit effort="1000.00000" lower="-3.14" upper="3.14" velocity="0.00000"/>
		<dynamics damping="1.0" friction="0.0001"/>
		<origin rpy="0.00000 0.0000 0.00000" xyz="0.00444 0.12440 -0.03839"/>
		<axis xyz="1.00000 0.00000 0.00000"/>
	</joint>
	<joint name="spine_2_ry" type="revolute">
		<parent link="spine_2_rx"/>
		<child link="spine_2_ry"/>
		<limit effort="1000.00000" lower="-3.14" upper="3.14" velocity="0.00000"/>
		<dynamics damping="1.0" friction="0.0001"/>
		<origin rpy="0.00000 0.0000 0.00000" xyz="0.00000 0.00000 0.00000"/>
		<axis xyz="0.00000 1.00000 0.00000"/>
	</joint>
	<joint name="spine_2_rz" type="revolute">
		<parent link="spine_2_ry"/>
		<child link="spine_2_rz"/>
		<limit effort="1000.00000" lower="-3.14" upper="3.14" velocity="0.00000"/>
		<dynamics damping="1.0" friction="0.0001"/>
		<origin rpy="0.00000 0.0000 0.00000" xyz="0.00000 0.00000 0.00000"/>
		<axis xyz="0.00000 0.00000 1.00000"/>
	</joint>
	<joint name="spine_2_rzdammy" type="fixed">
		<parent link="spine_2_rz"/>
		<child link="spine_2_limb"/>
		<origin rpy="0.00000 0.0000 0.00000" xyz="0.00000 0.00000 0.00000"/>
	</joint>
	<joint name="spine_3_rx" type="revolute">
		<parent link="spine_2_limb"/>
		<child link="spine_3_rx"/>
		<limit effort="1000.00000" lower="-3.14" upper="3.14" velocity="0.00000"/>
		<dynamics damping="1.0" friction="0.0001"/>
		<origin rpy="0.00000 0.0000 0.00000" xyz="0.00449 0.13796 0.02682"/>
		<axis xyz="1.00000 0.00000 0.00000"/>
	</joint>
	<joint name="spine_3_ry" type="revolute">
		<parent link="spine_3_rx"/>
		<child link="spine_3_ry"/>
		<limit effort="1000.00000" lower="-3.14" upper="3.14" velocity="0.00000"/>
		<dynamics damping="1.0" friction="0.0001"/>
		<origin rpy="0.00000 0.0000 0.00000" xyz="0.00000 0.00000 0.00000"/>
		<axis xyz="0.00000 1.00000 0.00000"/>
	</joint>
	<joint name="spine_3_rz" type="revolute">
		<parent link="spine_3_ry"/>
		<child link="spine_3_rz"/>
		<limit effort="1000.00000" lower="-3.14" upper="3.14" velocity="0.00000"/>
		<dynamics damping="1.0" friction="0.0001"/>
		<origin rpy="0.00000 0.0000 0.00000" xyz="0.00000 0.00000 0.00000"/>
		<axis xyz="0.00000 0.00000 1.00000"/>
	</joint>
	<joint name="spine_3_rzdammy" type="fixed">
		<parent link="spine_3_rz"/>
		<child link="spine_3_limb"/>
		<origin rpy="0.00000 0.0000 0.00000" xyz="0.00000 0.00000 0.00000"/>
	</joint>
	<joint name="spine_4_rx" type="revolute">
		<parent link="spine_3_limb"/>
		<child link="spine_4_rx"/>
		<limit effort="1000.00000" lower="-3.14" upper="3.14" velocity="0.00000"/>
		<dynamics damping="1.0" friction="0.0001"/>
		<origin rpy="0.00000 0.0000 0.00000" xyz="-0.00226 0.05603 0.00286"/>
		<axis xyz="1.00000 0.00000 0.00000"/>
	</joint>
	<joint name="spine_4_ry" type="revolute">
		<parent link="spine_4_rx"/>
		<child link="spine_4_ry"/>
		<limit effort="1000.00000" lower="-3.14" upper="3.14" velocity="0.00000"/>
		<dynamics damping="1.0" friction="0.0001"/>
		<origin rpy="0.00000 0.0000 0.00000" xyz="0.00000 0.00000 0.00000"/>
		<axis xyz="0.00000 1.00000 0.00000"/>
	</joint>
	<joint name="spine_4_rz" type="revolute">
		<parent link="spine_4_ry"/>
		<child link="spine_4_rz"/>
		<limit effort="1000.00000" lower="-3.14" upper="3.14" velocity="0.00000"/>
		<dynamics damping="1.0" friction="0.0001"/>
		<origin rpy="0.00000 0.0000 0.00000" xyz="0.00000 0.00000 0.00000"/>
		<axis xyz="0.00000 0.00000 1.00000"/>
	</joint>
	<joint name="spine_4_rzdammy" type="fixed">
		<parent link="spine_4_rz"/>
		<child link="spine_4_limb"/>
		<origin rpy="0.00000 0.0000 0.00000" xyz="0.00000 0.00000 0.00000"/>
	</joint>
	<joint name="neck_rx" type="revolute">
		<parent link="spine_4_limb"/>
		<child link="neck_rx"/>
		<limit effort="1000.00000" lower="-3.14" upper="3.14" velocity="0.00000"/>
		<dynamics damping="1.0" friction="0.0001"/>
		<origin rpy="0.00000 0.0000 0.00000" xyz="-0.01339 0.21164 -0.03347"/>
		<axis xyz="1.00000 0.00000 0.00000"/>
	</joint>
	<joint name="neck_ry" type="revolute">
		<parent link="neck_rx"/>
		<child link="neck_ry"/>
		<limit effort="1000.00000" lower="-3.14" upper="3.14" velocity="0.00000"/>
		<dynamics damping="1.0" friction="0.0001"/>
		<origin rpy="0.00000 0.0000 0.00000" xyz="0.00000 0.00000 0.00000"/>
		<axis xyz="0.00000 1.00000 0.00000"/>
	</joint>
	<joint name="neck_rz" type="revolute">
		<parent link="neck_ry"/>
		<child link="neck_rz"/>
		<limit effort="1000.00000" lower="-3.14" upper="3.14" velocity="0.00000"/>
		<dynamics damping="1.0" friction="0.0001"/>
		<origin rpy="0.00000 0.0000 0.00000" xyz="0.00000 0.00000 0.00000"/>
		<axis xyz="0.00000 0.00000 1.00000"/>
	</joint>
	<joint name="neck_rzdammy" type="fixed">
		<parent link="neck_rz"/>
		<child link="neck_limb"/>
		<origin rpy="0.00000 0.0000 0.00000" xyz="0.00000 0.00000 0.00000"/>
	</joint>
	<joint name="head_rx" type="revolute">
		<parent link="neck_limb"/>
		<child link="head_rx"/>
		<limit effort="1000.00000" lower="-3.14" upper="3.14" velocity="0.00000"/>
		<dynamics damping="1.0" friction="0.0001"/>
		<origin rpy="0.00000 0.0000 0.00000" xyz="0.01011 0.08894 0.05041"/>
		<axis xyz="1.00000 0.00000 0.00000"/>
	</joint>
	<joint name="head_ry" type="revolute">
		<parent link="head_rx"/>
		<child link="head_ry"/>
		<limit effort="1000.00000" lower="-3.14" upper="3.14" velocity="0.00000"/>
		<dynamics damping="1.0" friction="0.0001"/>
		<origin rpy="0.00000 0.0000 0.00000" xyz="0.00000 0.00000 0.00000"/>
		<axis xyz="0.00000 1.00000 0.00000"/>
	</joint>
	<joint name="head_rz" type="revolute">
		<parent link="head_ry"/>
		<child link="head_rz"/>
		<limit effort="1000.00000" lower="-3.14" upper="3.14" velocity="0.00000"/>
		<dynamics damping="1.0" friction="0.0001"/>
		<origin rpy="0.00000 0.0000 0.00000" xyz="0.00000 0.00000 0.00000"/>
		<axis xyz="0.00000 0.00000 1.00000"/>
	</joint>
	<joint name="head_rzdammy" type="fixed">
		<parent link="head_rz"/>
		<child link="head_limb"/>
		<origin rpy="0.00000 0.0000 0.00000" xyz="0.00000 0.00000 0.00000"/>
	</joint>
	<joint name="left_clavicle_rx" type="revolute">
		<parent link="spine_4_limb"/>
		<child link="left_clavicle_rx"/>
		<limit effort="1000.00000" lower="-3.14" upper="3.14" velocity="0.00000"/>
		<dynamics damping="1.0" friction="0.0001"/>
		<origin rpy="0.00000 0.0000 0.00000" xyz="0.07170 0.11400 -0.01890"/>
		<axis xyz="1.00000 0.00000 0.00000"/>
	</joint>
	<joint name="left_clavicle_ry" type="revolute">
		<parent link="left_clavicle_rx"/>
		<child link="left_clavicle_ry"/>
		<limit effort="1000.00000" lower="-3.14" upper="3.14" velocity="0.00000"/>
		<dynamics damping="1.0" friction="0.0001"/>
		<origin rpy="0.00000 0.0000 0.00000" xyz="0.00000 0.00000 0.00000"/>
		<axis xyz="0.00000 1.00000 0.00000"/>
	</joint>
	<joint name="left_clavicle_rz" type="revolute">
		<parent link="left_clavicle_ry"/>
		<child link="left_clavicle_rz"/>
		<limit effort="1000.00000" lower="-3.14" upper="3.14" velocity="0.00000"/>
		<dynamics damping="1.0" friction="0.0001"/>
		<origin rpy="0.00000 0.0000 0.00000" xyz="0.00000 0.00000 0.00000"/>
		<axis xyz="0.00000 0.00000 1.00000"/>
	</joint>
	<joint name="left_clavicle_rzdammy" type="fixed">
		<parent link="left_clavicle_rz"/>
		<child link="left_clavicle_limb"/>
		<origin rpy="0.00000 0.0000 0.00000" xyz="0.00000 0.00000 0.00000"/>
	</joint>
	<joint name="left_shoulder_rx" type="revolute">
		<parent link="left_clavicle_limb"/>
		<child link="left_shoulder_rx"/>
		<limit effort="1000.00000" lower="-3.14" upper="3.14" velocity="0.00000"/>
		<dynamics damping="1.0" friction="0.0001"/>
		<origin rpy="0.00000 0.0000 0.00000" xyz="0.12292 0.04521 -0.01905"/>
		<axis xyz="1.00000 0.00000 0.00000"/>
	</joint>
	<joint name="left_shoulder_ry" type="revolute">
		<parent link="left_shoulder_rx"/>
		<child link="left_shoulder_ry"/>
		<limit effort="1000.00000" lower="-3.14" upper="3.14" velocity="0.00000"/>
		<dynamics damping="1.0" friction="0.0001"/>
		<origin rpy="0.00000 0.0000 0.00000" xyz="0.00000 0.00000 0.00000"/>
		<axis xyz="0.00000 1.00000 0.00000"/>
	</joint>
	<joint name="left_shoulder_rz" type="revolute">
		<parent link="left_shoulder_ry"/>
		<child link="left_shoulder_rz"/>
		<limit effort="1000.00000" lower="-3.14" upper="3.14" velocity="0.00000"/>
		<dynamics damping="1.0" friction="0.0001"/>
		<origin rpy="0.00000 0.0000 0.00000" xyz="0.00000 0.00000 0.00000"/>
		<axis xyz="0.00000 0.00000 1.00000"/>
	</joint>
	<joint name="left_shoulder_rzdammy" type="fixed">
		<parent link="left_shoulder_rz"/>
		<child link="left_shoulder_limb"/>
		<origin rpy="0.00000 0.0000 0.00000" xyz="0.00000 0.00000 0.00000"/>
	</joint>
	<joint name="left_elbow_rx" type="revolute">
		<parent link="left_shoulder_limb"/>
		<child link="left_elbow_rx"/>
		<limit effort="1000.00000" lower="-3.14" upper="3.14" velocity="0.00000"/>
		<dynamics damping="1.0" friction="0.0001"/>
		<origin rpy="0.00000 0.0000 0.00000" xyz="0.25533 -0.01565 -0.02295"/>
		<axis xyz="1.00000 0.00000 0.00000"/>
	</joint>
	<joint name="left_elbow_ry" type="revolute">
		<parent link="left_elbow_rx"/>
		<child link="left_elbow_ry"/>
		<limit effort="1000.00000" lower="-3.14" upper="3.14" velocity="0.00000"/>
		<dynamics damping="1.0" friction="0.0001"/>
		<origin rpy="0.00000 0.0000 0.00000" xyz="0.00000 0.00000 0.00000"/>
		<axis xyz="0.00000 1.00000 0.00000"/>
	</joint>
	<joint name="left_elbow_rz" type="revolute">
		<parent link="left_elbow_ry"/>
		<child link="left_elbow_rz"/>
		<limit effort="1000.00000" lower="-3.14" upper="3.14" velocity="0.00000"/>
		<dynamics damping="1.0" friction="0.0001"/>
		<origin rpy="0.00000 0.0000 0.00000" xyz="0.00000 0.00000 0.00000"/>
		<axis xyz="0.00000 0.00000 1.00000"/>
	</joint>
	<joint name="left_elbow_rzdammy" type="fixed">
		<parent link="left_elbow_rz"/>
		<child link="left_elbow_limb"/>
		<origin rpy="0.00000 0.0000 0.00000" xyz="0.00000 0.00000 0.00000"/>
	</joint>
	<joint name="left_lowarm_rx" type="revolute">
		<parent link="left_elbow_limb"/>
		<child link="left_lowarm_rx"/>
		<limit effort="1000.00000" lower="-3.14" upper="3.14" velocity="0.00000"/>
		<dynamics damping="1.0" friction="0.0001"/>
		<origin rpy="0.00000 0.0000 0.00000" xyz="0.26571 0.01270 -0.00737"/>
		<axis xyz="1.00000 0.00000 0.00000"/>
	</joint>
	<joint name="left_lowarm_ry" type="revolute">
		<parent link="left_lowarm_rx"/>
		<child link="left_lowarm_ry"/>
		<limit effort="1000.00000" lower="-3.14" upper="3.14" velocity="0.00000"/>
		<dynamics damping="1.0" friction="0.0001"/>
		<origin rpy="0.00000 0.0000 0.00000" xyz="0.00000 0.00000 0.00000"/>
		<axis xyz="0.00000 1.00000 0.00000"/>
	</joint>
	<joint name="left_lowarm_rz" type="revolute">
		<parent link="left_lowarm_ry"/>
		<child link="left_lowarm_rz"/>
		<limit effort="1000.00000" lower="-3.14" upper="3.14" velocity="0.00000"/>
		<dynamics damping="1.0" friction="0.0001"/>
		<origin rpy="0.00000 0.0000 0.00000" xyz="0.00000 0.00000 0.00000"/>
		<axis xyz="0.00000 0.00000 1.00000"/>
	</joint>
	<joint name="left_lowarm_rzdammy" type="fixed">
		<parent link="left_lowarm_rz"/>
		<child link="left_lowarm_limb"/>
		<origin rpy="0.00000 0.0000 0.00000" xyz="0.00000 0.00000 0.00000"/>
	</joint>
	<joint name="left_hand_rx" type="revolute">
		<parent link="left_lowarm_limb"/>
		<child link="left_hand_rx"/>
		<limit effort="1000.00000" lower="-3.14" upper="3.14" velocity="0.00000"/>
		<dynamics damping="1.0" friction="0.0001"/>
		<origin rpy="0.00000 0.0000 0.00000" xyz="0.08669 -0.01064 -0.01559"/>
	    <axis xyz="1.00000 0.00000 0.00000"/>
	</joint>
	<joint name="left_hand_ry" type="revolute">
		<parent link="left_hand_rx"/>
		<child link="left_hand_ry"/>
		<limit effort="1000.00000" lower="-3.14" upper="3.14" velocity="0.00000"/>
		<dynamics damping="1.0" friction="0.0001"/>
		<origin rpy="0.00000 0.0000 0.00000" xyz="0.00000 0.00000 0.00000"/>
		<axis xyz="0.00000 1.00000 0.00000"/>
	</joint>
	<joint name="left_hand_rz" type="revolute">
		<parent link="left_hand_ry"/>
		<child link="left_hand_rz"/>
		<limit effort="1000.00000" lower="-3.14" upper="3.14" velocity="0.00000"/>
		<dynamics damping="1.0" friction="0.0001"/>
		<origin rpy="0.00000 0.0000 0.00000" xyz="0.00000 0.00000 0.00000"/>
		<axis xyz="0.00000 0.00000 1.00000"/>
	</joint>
	<joint name="left_hand_rzdammy" type="fixed">
		<parent link="left_hand_rz"/>
		<child link="left_hand_limb"/>
		<origin rpy="0.00000 0.0000 0.00000" xyz="0.00000 0.00000 0.00000"/>
	</joint>
	<joint name="right_clavicle_rx" type="revolute">
		<parent link="spine_4_limb"/>
		<child link="right_clavicle_rx"/>
		<limit effort="1000.00000" lower="-3.14" upper="3.14" velocity="0.00000"/>
		<dynamics damping="1.0" friction="0.0001"/>
		<origin rpy="0.00000 0.0000 0.00000" xyz="-0.08295 0.11247 -0.02371"/>
	    <axis xyz="1.00000 0.00000 0.00000"/>
	</joint>
	<joint name="right_clavicle_ry" type="revolute">
		<parent link="right_clavicle_rx"/>
		<child link="right_clavicle_ry"/>
		<limit effort="1000.00000" lower="-3.14" upper="3.14" velocity="0.00000"/>
		<dynamics damping="1.0" friction="0.0001"/>
		<origin rpy="0.00000 0.0000 0.00000" xyz="0.00000 0.00000 0.00000"/>
		<axis xyz="0.00000 1.00000 0.00000"/>
	</joint>
	<joint name="right_clavicle_rz" type="revolute">
		<parent link="right_clavicle_ry"/>
		<child link="right_clavicle_rz"/>
		<limit effort="1000.00000" lower="-3.14" upper="3.14" velocity="0.00000"/>
		<dynamics damping="1.0" friction="0.0001"/>
		<origin rpy="0.00000 0.0000 0.00000" xyz="0.00000 0.00000 0.00000"/>
		<axis xyz="0.00000 0.00000 1.00000"/>
	</joint>
	<joint name="right_clavicle_rzdammy" type="fixed">
		<parent link="right_clavicle_rz"/>
		<child link="right_clavicle_limb"/>
		<origin rpy="0.00000 0.0000 0.00000" xyz="0.00000 0.00000 0.00000"/>
	</joint>
	<joint name="right_shoulder_rx" type="revolute">
		<parent link="right_clavicle_limb"/>
		<child link="right_shoulder_rx"/>
		<limit effort="1000.00000" lower="-3.14" upper="3.14" velocity="0.00000"/>
		<dynamics damping="1.0" friction="0.0001"/>
		<origin rpy="0.00000 0.0000 0.00000" xyz="-0.11323 0.04685 -0.00847"/>
		<axis xyz="1.00000 0.00000 0.00000"/>
	</joint>
	<joint name="right_shoulder_ry" type="revolute">
		<parent link="right_shoulder_rx"/>
		<child link="right_shoulder_ry"/>
		<limit effort="1000.00000" lower="-3.14" upper="3.14" velocity="0.00000"/>
		<dynamics damping="1.0" friction="0.0001"/>
		<origin rpy="0.00000 0.0000 0.00000" xyz="0.00000 0.00000 0.00000"/>
		<axis xyz="0.00000 1.00000 0.00000"/>
	</joint>
	<joint name="right_shoulder_rz" type="revolute">
		<parent link="right_shoulder_ry"/>
		<child link="right_shoulder_rz"/>
		<limit effort="1000.00000" lower="-3.14" upper="3.14" velocity="0.00000"/>
		<dynamics damping="1.0" friction="0.0001"/>
		<origin rpy="0.00000 0.0000 0.00000" xyz="0.00000 0.00000 0.00000"/>
		<axis xyz="0.00000 0.00000 1.00000"/>
	</joint>
	<joint name="right_shoulder_rzdammy" type="fixed">
		<parent link="right_shoulder_rz"/>
		<child link="right_shoulder_limb"/>
		<origin rpy="0.00000 0.0000 0.00000" xyz="0.00000 0.00000 0.00000"/>
	</joint>
	<joint name="right_elbow_rx" type="revolute">
		<parent link="right_shoulder_limb"/>
		<child link="right_elbow_rx"/>
		<limit effort="1000.00000" lower="-3.14" upper="3.14" velocity="0.00000"/>
		<dynamics damping="1.0" friction="0.0001"/>
		<origin rpy="0.00000 0.0000 0.00000" xyz="-0.26013 -0.01437 -0.03127"/>
		<axis xyz="1.00000 0.00000 0.00000"/>
	</joint>
	<joint name="right_elbow_ry" type="revolute">
		<parent link="right_elbow_rx"/>
		<child link="right_elbow_ry"/>
		<limit effort="1000.00000" lower="-3.14" upper="3.14" velocity="0.00000"/>
		<dynamics damping="1.0" friction="0.0001"/>
		<origin rpy="0.00000 0.0000 0.00000" xyz="0.00000 0.00000 0.00000"/>
	    <axis xyz="0.00000 1.00000 0.00000"/>
	</joint>
	<joint name="right_elbow_rz" type="revolute">
		<parent link="right_elbow_ry"/>
		<child link="right_elbow_rz"/>
		<limit effort="1000.00000" lower="-3.14" upper="3.14" velocity="0.00000"/>
		<dynamics damping="1.0" friction="0.0001"/>
		<origin rpy="0.00000 0.0000 0.00000" xyz="0.00000 0.00000 0.00000"/>
		<axis xyz="0.00000 0.00000 1.00000"/>
	</joint>
	<joint name="right_elbow_rzdammy" type="fixed">
		<parent link="right_elbow_rz"/>
		<child link="right_elbow_limb"/>
		<origin rpy="0.00000 0.0000 0.00000" xyz="0.00000 0.00000 0.00000"/>
	</joint>
	<joint name="right_lowarm_rx" type="revolute">
		<parent link="right_elbow_limb"/>
		<child link="right_lowarm_rx"/>
		<limit effort="1000.00000" lower="-3.14" upper="3.14" velocity="0.00000"/>
		<dynamics damping="1.0" friction="0.0001"/>
		<origin rpy="0.00000 0.0000 0.00000" xyz="-0.26911 0.00679 -0.00603"/>
		<axis xyz="1.00000 0.00000 0.00000"/>
	</joint>
	<joint name="right_lowarm_ry" type="revolute">
		<parent link="right_lowarm_rx"/>
		<child link="right_lowarm_ry"/>
		<limit effort="1000.00000" lower="-3.14" upper="3.14" velocity="0.00000"/>
		<dynamics damping="1.0" friction="0.0001"/>
		<origin rpy="0.00000 0.0000 0.00000" xyz="0.00000 0.00000 0.00000"/>
		<axis xyz="0.00000 1.00000 0.00000"/>
	</joint>
	<joint name="right_lowarm_rz" type="revolute">
		<parent link="right_lowarm_ry"/>
		<child link="right_lowarm_rz"/>
		<limit effort="1000.00000" lower="-3.14" upper="3.14" velocity="0.00000"/>
		<dynamics damping="1.0" friction="0.0001"/>
		<origin rpy="0.00000 0.0000 0.00000" xyz="0.00000 0.00000 0.00000"/>
		<axis xyz="0.00000 0.00000 1.00000"/>
	</joint>
	<joint name="right_lowarm_rzdammy" type="fixed">
		<parent link="right_lowarm_rz"/>
		<child link="right_lowarm_limb"/>
		<origin rpy="0.00000 0.0000 0.00000" xyz="0.00000 0.00000 0.00000"/>
	</joint>
	<joint name="right_hand_rx" type="revolute">
		<parent link="right_lowarm_limb"/>
		<child link="right_hand_rx"/>
		<limit effort="1000.00000" lower="-3.14" upper="3.14" velocity="0.00000"/>
		<dynamics damping="1.0" friction="0.0001"/>
		<origin rpy="0.00000 0.0000 0.00000" xyz="-0.08875 -0.00865 -0.01011"/>
		<axis xyz="1.00000 0.00000 0.00000"/>
	</joint>
	<joint name="right_hand_ry" type="revolute">
		<parent link="right_hand_rx"/>
		<child link="right_hand_ry"/>
		<limit effort="1000.00000" lower="-3.14" upper="3.14" velocity="0.00000"/>
		<dynamics damping="1.0" friction="0.0001"/>
		<origin rpy="0.00000 0.0000 0.00000" xyz="0.00000 0.00000 0.00000"/>
		<axis xyz="0.00000 1.00000 0.00000"/>
	</joint>
	<joint name="right_hand_rz" type="revolute">
		<parent link="right_hand_ry"/>
		<child link="right_hand_rz"/>
		<limit effort="1000.00000" lower="-3.14" upper="3.14" velocity="0.00000"/>
		<dynamics damping="1.0" friction="0.0001"/>
		<origin rpy="0.00000 0.0000 0.00000" xyz="0.00000 0.00000 0.00000"/>
		<axis xyz="0.00000 0.00000 1.00000"/>
	</joint>
	<joint name="right_hand_rzdammy" type="fixed">
		<parent link="right_hand_rz"/>
		<child link="right_hand_limb"/>
		<origin rpy="0.00000 0.0000 0.00000" xyz="0.00000 0.00000 0.00000"/>
	</joint>
</robot>